Workbook

Sheet Start
B2: WORLD CUP 2026 POOL - KNOCKOUTS
B5: Reveni · Part 2 of 2 · Jun 28 - Jul 19
B8: BEFORE YOU START
B10: Make a copy of this file and rename it to: WorldCup_Knockouts_YourName.xlsx
B11: Don't edit the original. Send your renamed copy to the admin when finished.
B13: HOW TO PLAY (PART 2 - KNOCKOUTS)
B15: 1. Enter your name in the 'You' tab.
B16: 2. Go to 'Bracket': the 16 Round of 32 matches are ALREADY FILLED with the real teams.
B17: Enter home goals and away goals (two separate cells) for each match at 90 minutes.
B18: 3. If you predict a draw, use the 'If tied' dropdown to indicate who advances.
B19: No penalty points - just decide who passes if tied at 90'.
B20: 4. Teams advance automatically to the next round (R16 → QF → SF → 3rd place → Final).
... B34: • Top Scorer: 8 pts | Ballon d'Or (Best Player): 8 pts

Sheet You
B2: YOUR DETAILS
B4: Name: | C4: JE

Sheet Bracket
B2: BRACKET - Your predictions
B3: Round of 32 teams are filled in. Enter home goals and away goals at 90 minutes. If tied, use the dropdown to pick who advances.
B5: ROUND OF 32 (Jun 28 - Jul 3) | J5: Loser/Date
B6: HOME | C6: Goals 90' | E6: Goals 90' | F6: AWAY | G6: If tied | H6: Winner
B7: Germany | C7: 2 | D7: - | E7: 1 | F7: Paraguay | H7: =IFERROR(IF(AND(C7<>"",E7<>""),IF(C7>E7,B7,IF(E7>C7,F7,IF(G7="Home",B7,IF(G7="Away",F7,"")))),""),"") | J7: Jun 29
B8: France | C8: 2 | D8: - | E8: 1 | F8: Sweden | H8: =IFERROR(IF(AND(C8<>"",E8<>""),IF(C8>E8,B8,IF(E8>C8,F8,IF(G8="Home",B8,IF(G8="Away",F8,"")))),""),"") | J8: Jun 30
B9: South Africa | C9: 1 | D9: - | E9: 2 | F9: Canada | H9: =IFERROR(IF(AND(C9<>"",E9<>""),IF(C9>E9,B9,IF(E9>C9,F9,IF(G9="Home",B9,IF(G9="Away",F9,"")))),""),"") | J9: Jun 28
B10: Netherlands | C10: 2 | D10: - | E10: 1 | F10: Morocco | H10: =IFERROR(IF(AND(C10<>"",E10<>""),IF(C10>E10,B10,IF(E10>C10,F10,IF(G10="Home",B10,IF(G10="Away",F10,"")))),""),"") | J10: Jun 29
B11: Portugal | C11: 2 | D11: - | E11: 1 | F11: Croatia | H11: =IFERROR(IF(AND(C11<>"",E11<>""),IF(C11>E11,B11,IF(E11>C11,F11,IF(G11="Home",B11,IF(G11="Away",F11,"")))),""),"") | J11: Jul 2
B12: Spain | C12: 2 | D12: - | E12: 1 | F12: Austria | H12: =IFERROR(IF(AND(C12<>"",E12<>""),IF(C12>E12,B12,IF(E12>C12,F12,IF(G12="Home",B12,IF(G12="Away",F12,"")))),""),"") | J12: Jul 2
B13: USA | C13: 2 | D13: - | E13: 1 | F13: Bosnia-Herz. | H13: =IFERROR(IF(AND(C13<>"",E13<>""),IF(C13>E13,B13,IF(E13>C13,F13,IF(G13="Home",B13,IF(G13="Away",F13,"")))),""),"") | J13: Jul 1
B14: Belgium | C14: 2 | D14: - | E14: 1 | F14: Senegal | H14: =IFERROR(IF(AND(C14<>"",E14<>""),IF(C14>E14,B14,IF(E14>C14,F14,IF(G14="Home",B14,IF(G14="Away",F14,"")))),""),"") | J14: Jul 1
B15: Brazil | C15: 2 | D15: - | E15: 1 | F15: Japan | H15: =IFERROR(IF(AND(C15<>"",E15<>""),IF(C15>E15,B15,IF(E15>C15,F15,IF(G15="Home",B15,IF(G15="Away",F15,"")))),""),"") | J15: Jun 29
B16: Ivory Coast | C16: 1 | D16: - | E16: 2 | F16: Norway | H16: =IFERROR(IF(AND(C16<>"",E16<>""),IF(C16>E16,B16,IF(E16>C16,F16,IF(G16="Home",B16,IF(G16="Away",F16,"")))),""),"") | J16: Jun 30
B17: Mexico | C17: 2 | D17: - | E17: 1 | F17: Ecuador | H17: =IFERROR(IF(AND(C17<>"",E17<>""),IF(C17>E17,B17,IF(E17>C17,F17,IF(G17="Home",B17,IF(G17="Away",F17,"")))),""),"") | J17: Jun 30
B18: England | C18: 2 | D18: - | E18: 1 | F18: DR Congo | H18: =IFERROR(IF(AND(C18<>"",E18<>""),IF(C18>E18,B18,IF(E18>C18,F18,IF(G18="Home",B18,IF(G18="Away",F18,"")))),""),"") | J18: Jul 1
... B22: Colombia | C22: 2 | D22: - | E22: 1 | F22: Ghana | H22: =IFERROR(IF(AND(C22<>"",E22<>""),IF(C22>E22,B22,IF(E22>C22,F22,IF(G22="Home",B22,IF(G22="Away",F22,"")))),""),"") | J22: Jul 3
B24: ROUND OF 16 (Jul 5 - 8)
B25: HOME | C25: Goals 90' | E25: Goals 90' | F25: AWAY | G25: If tied | H25: Winner
B26: =H7 | C26: 1 | D26: - | E26: 2 | F26: =H8 | H26: =IFERROR(IF(AND(C26<>"",E26<>""),IF(C26>E26,B26,IF(E26>C26,F26,IF(G26="Home",B26,IF(G26="Away",F26,"")))),""),"")
B27: =H9 | C27: 1 | D27: - | E27: 2 | F27: =H10 | H27: =IFERROR(IF(AND(C27<>"",E27<>""),IF(C27>E27,B27,IF(E27>C27,F27,IF(G27="Home",B27,IF(G27="Away",F27,"")))),""),"")
B28: =H11 | C28: 1 | D28: - | E28: 2 | F28: =H12 | H28: =IFERROR(IF(AND(C28<>"",E28<>""),IF(C28>E28,B28,IF(E28>C28,F28,IF(G28="Home",B28,IF(G28="Away",F28,"")))),""),"")
B29: =H13 | C29: 1 | D29: - | E29: 2 | F29: =H14 | H29: =IFERROR(IF(AND(C29<>"",E29<>""),IF(C29>E29,B29,IF(E29>C29,F29,IF(G29="Home",B29,IF(G29="Away",F29,"")))),""),"")
B30: =H15 | C30: 2 | D30: - | E30: 1 | F30: =H16 | H30: =IFERROR(IF(AND(C30<>"",E30<>""),IF(C30>E30,B30,IF(E30>C30,F30,IF(G30="Home",B30,IF(G30="Away",F30,"")))),""),"")
B31: =H17 | C31: 1 | D31: - | E31: 2 | F31: =H18 | H31: =IFERROR(IF(AND(C31<>"",E31<>""),IF(C31>E31,B31,IF(E31>C31,F31,IF(G31="Home",B31,IF(G31="Away",F31,"")))),""),"")
B32: =H19 | C32: 2 | D32: - | E32: 1 | F32: =H20 | H32: =IFERROR(IF(AND(C32<>"",E32<>""),IF(C32>E32,B32,IF(E32>C32,F32,IF(G32="Home",B32,IF(G32="Away",F32,"")))),""),"")
B33: =H21 | C33: 1 | D33: - | E33: 2 | F33: =H22 | H33: =IFERROR(IF(AND(C33<>"",E33<>""),IF(C33>E33,B33,IF(E33>C33,F33,IF(G33="Home",B33,IF(G33="Away",F33,"")))),""),"")
B35: QUARTER-FINALS (Jul 9 - 11)
B36: HOME | C36: Goals 90' | E36: Goals 90' | F36: AWAY | G36: If tied | H36: Winner
B37: =H26 | C37: 2 | D37: - | E37: 1 | F37: =H27 | H37: =IFERROR(IF(AND(C37<>"",E37<>""),IF(C37>E37,B37,IF(E37>C37,F37,IF(G37="Home",B37,IF(G37="Away",F37,"")))),""),"")
B38: =H28 | C38: 1 | D38: - | E38: 2 | F38: =H29 | H38: =IFERROR(IF(AND(C38<>"",E38<>""),IF(C38>E38,B38,IF(E38>C38,F38,IF(G38="Home",B38,IF(G38="Away",F38,"")))),""),"")
B39: =H30 | C39: 1 | D39: - | E39: 2 | F39: =H31 | H39: =IFERROR(IF(AND(C39<>"",E39<>""),IF(C39>E39,B39,IF(E39>C39,F39,IF(G39="Home",B39,IF(G39="Away",F39,"")))),""),"")
B40: =H32 | C40: 2 | D40: - | E40: 1 | F40: =H33 | H40: =IFERROR(IF(AND(C40<>"",E40<>""),IF(C40>E40,B40,IF(E40>C40,F40,IF(G40="Home",B40,IF(G40="Away",F40,"")))),""),"")
B42: SEMI-FINALS (Jul 14 - 15)
B43: HOME | C43: Goals 90' | E43: Goals 90' | F43: AWAY | G43: If tied | H43: Winner
B44: =H37 | C44: 2 | D44: - | E44: 1 | F44: =H38 | H44: =IFERROR(IF(AND(C44<>"",E44<>""),IF(C44>E44,B44,IF(E44>C44,F44,IF(G44="Home",B44,IF(G44="Away",F44,"")))),""),"") | J44: =IFERROR(IF(AND(C44<>"",E44<>""),IF(C44<E44,B44,IF(E44<C44,F44,IF(G44="Home",F44,IF(G44="Away",B44,"")))),""),"")
B45: =H39 | C45: 1 | D45: - | E45: 2 | F45: =H40 | H45: =IFERROR(IF(AND(C45<>"",E45<>""),IF(C45>E45,B45,IF(E45>C45,F45,IF(G45="Home",B45,IF(G45="Away",F45,"")))),""),"") | J45: =IFERROR(IF(AND(C45<>"",E45<>""),IF(C45<E45,B45,IF(E45<C45,F45,IF(G45="Home",F45,IF(G45="Away",B45,"")))),""),"")
B47: THIRD AND FOURTH PLACE (Jul 18)
B48: HOME | C48: Goals 90' | E48: Goals 90' | F48: AWAY | G48: If tied | H48: 3rd place
B49: =J44 | C49: 2 | D49: - | E49: 1 | F49: =J45 | H49: =IFERROR(IF(AND(C49<>"",E49<>""),IF(C49>E49,B49,IF(E49>C49,F49,IF(G49="Home",B49,IF(G49="Away",F49,"")))),""),"")
...

Sheet Awards
B2: SPECIAL AWARDS
B3: Pick which players you think will win the individual awards.
B5: Award | C5: Your pick | D5: Points
B6: Top Scorer | C6: Kylian Mbappé | D6: 8 pts
B7: Ballon d'Or | C7: Kylian Mbappé | D7: 8 pts

Sheet Admin export
B2: ADMIN EXPORT - Copy & paste into the admin sheet
B3: Select from row 5 down, copy, paste into the admin sheet 'Raw data' tab in your column.
B5: Concept | C5: Home / Value | D5: Away
B6: PARTICIPANT | C6: =You!C4
B7: ROUND OF 32
B8: R32-M1 score | C8: =Bracket!C7 | D8: =Bracket!E7
B9: R32-M1 tiebreaker | C9: =Bracket!G7
B10: R32-M1 winner | C10: =Bracket!H7
B11: R32-M2 score | C11: =Bracket!C8 | D11: =Bracket!E8
B12: R32-M2 tiebreaker | C12: =Bracket!G8
B13: R32-M2 winner | C13: =Bracket!H8
B14: R32-M3 score | C14: =Bracket!C9 | D14: =Bracket!E9
B15: R32-M3 tiebreaker | C15: =Bracket!G9
B16: R32-M3 winner | C16: =Bracket!H9
B17: R32-M4 score | C17: =Bracket!C10 | D17: =Bracket!E10
B18: R32-M4 tiebreaker | C18: =Bracket!G10
B19: R32-M4 winner | C19: =Bracket!H10
B20: R32-M5 score | C20: =Bracket!C11 | D20: =Bracket!E11
B21: R32-M5 tiebreaker | C21: =Bracket!G11
B22: R32-M5 winner | C22: =Bracket!H11
B23: R32-M6 score | C23: =Bracket!C12 | D23: =Bracket!E12
B24: R32-M6 tiebreaker | C24: =Bracket!G12
B25: R32-M6 winner | C25: =Bracket!H12
B26: R32-M7 score | C26: =Bracket!C13 | D26: =Bracket!E13
B27: R32-M7 tiebreaker | C27: =Bracket!G13
B28: R32-M7 winner | C28: =Bracket!H13
B29: R32-M8 score | C29: =Bracket!C14 | D29: =Bracket!E14
B30: R32-M8 tiebreaker | C30: =Bracket!G14
B31: R32-M8 winner | C31: =Bracket!H14
B32: R32-M9 score | C32: =Bracket!C15 | D32: =Bracket!E15
B33: R32-M9 tiebreaker | C33: =Bracket!G15
B34: R32-M9 winner | C34: =Bracket!H15
B35: R32-M10 score | C35: =Bracket!C16 | D35: =Bracket!E16
B36: R32-M10 tiebreaker | C36: =Bracket!G16
B37: R32-M10 winner | C37: =Bracket!H16
B38: R32-M11 score | C38: =Bracket!C17 | D38: =Bracket!E17
B39: R32-M11 tiebreaker | C39: =Bracket!G17
B40: R32-M11 winner | C40: =Bracket!H17
B41: R32-M12 score | C41: =Bracket!C18 | D41: =Bracket!E18
B42: R32-M12 tiebreaker | C42: =Bracket!G18
...
