Workbook

Sheet Start
B2: WORLD CUP 2026 POOL - ADMIN
B6: WORKFLOW
B8: 1. Participants send you their files with the 'Admin export' tab filled in.
B9: 2. In 'Raw data', paste each participant's columns C and D into their slot.
B10: Each participant uses TWO columns: home goals + away goals (or value).
B11: 3. Type the real name in row 6 (home column of each pair).
B12: 4. In 'Real results', fill in actual match results as games are played.
B13: 5. 'Calculation' and 'Standings' tabs update automatically.
B15: WORKS FOR BOTH OPTIONS (OP1 + OP2)
B16: Both Option 1 (all-in-one) and Option 2 (groups + knockouts split) use the same
B17: export format, so this admin handles both.
B19: SCORING SYSTEM
... B31: • Top Scorer: 8 pts | Ballon d'Or: 8 pts

Sheet Real results
B2: REAL RESULTS
B3: Fill in real results as matches are played. Score rows use two cells: Home and Away.
B5: Concept | C5: Home / Value | D5: Away
B6: GROUP STAGE SCORES
B7: GA-M1: Mexico vs South Africa
B8: GA-M2: South Korea vs Czech Rep.
B9: GA-M3: Czech Rep. vs South Africa
B10: GA-M4: Mexico vs South Korea
B11: GA-M5: Czech Rep. vs Mexico
B12: GA-M6: South Africa vs South Korea
B13: GB-M1: Canada vs Bosnia-Herz.
B14: GB-M2: Qatar vs Switzerland
B15: GB-M3: Switzerland vs Bosnia-Herz.
B16: GB-M4: Canada vs Qatar
B17: GB-M5: Switzerland vs Canada
... B229: Ballon d'Or

Sheet Raw data
B2: RAW DATA - paste participant exports here
B3: Each participant uses TWO columns. Paste their 'Admin export' columns C+D into their slot. Row 6 holds their real name (in the Home column).
B5: CONCEPT | C5: P1 | E5: P2 | G5: P3 | I5: P4 | K5: P5 | M5: P6 | O5: P7 | Q5: P8 | S5: P9 | U5: P10 | W5: P11 | Y5: P12 | AA5: P13 | AC5: P14 | AE5: P15 | AG5: P16 | AI5: P17 | AK5: P18 | AM5: P19 | AO5: P20 | AQ5: P21 | AS5: P22 | AU5: P23 | AW5: P24 | AY5: P25 | BA5: P26 | BC5: P27 | BE5: P28 | BG5: P29 | BI5: P30
B6: GROUP STAGE SCORES | C6: Matt | E6: Fer | G6: Pano | I6: Tere | K6: Nadia | M6: Jose | O6: Lucía | Q6: Kike | S6: Paibol | U6: Pablo | W6: Almu | Y6: Juanorro | AA6: Cillian | AC6: July | AE6: Toño | AG6: Juanin | AI6: Meg | AK6: Irene | AM6: Andy | AO6: Adri | AQ6: Ben | AS6: Gon | AU6: Mile | AW6: Cami | AY6: Hugo | BA6: Jaime | BC6: Emilio | BE6: Manu
B7: GA-M1: Mexico vs South Africa | C7: 2 | D7: 1 | E7: 2 | F7: 0 | G7: 3 | H7: 0 | I7: 3 | J7: 1 | K7: 3 | L7: 1 | M7: 2 | N7: 1 | O7: 1 | P7: 1 | Q7: 2 | R7: 0 | S7: 2 | T7: 0 | U7: 2 | V7: 0 | W7: 2 | X7: 1 | Y7: 1 | Z7: 1 | AA7: 2 | AB7: 0 | AC7: 1 | AD7: 0 | AE7: 2 | AF7: 0 | AG7: 2 | AH7: 0 | AI7: 2 | AJ7: 1 | AK7: 2 | AL7: 0 | AM7: 3 | AN7: 0 | AO7: 2 | AP7: 0 | AQ7: 2 | AR7: 0 | AS7: 2 | AT7: 1 | AU7: 2 | AV7: 0 | AW7: 2 | AX7: 1 | AY7: 3 | AZ7: 1 | BA7: 2 | BB7: 0 | BC7: 2 | BD7: 1 | BE7: 2 | BF7: 0
B8: GA-M2: South Korea vs Czech Rep. | C8: 1 | D8: 1 | E8: 1 | F8: 1 | G8: 1 | H8: 1 | I8: 2 | J8: 1 | K8: 1 | L8: 2 | M8: 2 | N8: 1 | O8: 2 | P8: 0 | Q8: 2 | R8: 1 | S8: 1 | T8: 1 | U8: 1 | V8: 0 | W8: 2 | X8: 0 | Y8: 1 | Z8: 1 | AA8: 1 | AB8: 1 | AC8: 1 | AD8: 2 | AE8: 1 | AF8: 1 | AG8: 1 | AH8: 0 | AI8: 0 | AJ8: 2 | AK8: 2 | AL8: 1 | AM8: 1 | AN8: 1 | AO8: 1 | AP8: 1 | AQ8: 1 | AR8: 1 | AS8: 1 | AT8: 1 | AU8: 1 | AV8: 1 | AW8: 1 | AX8: 1 | AY8: 2 | AZ8: 0 | BA8: 1 | BB8: 1 | BC8: 1 | BD8: 1 | BE8: 1 | BF8: 1
B9: GA-M3: Czech Rep. vs South Africa | C9: 2 | D9: 0 | E9: 1 | F9: 0 | G9: 1 | H9: 0 | I9: 2 | J9: 0 | K9: 2 | L9: 0 | M9: 2 | N9: 1 | O9: 1 | P9: 0 | Q9: 2 | R9: 1 | S9: 1 | T9: 1 | U9: 2 | V9: 1 | W9: 1 | X9: 1 | Y9: 2 | Z9: 0 | AA9: 2 | AB9: 1 | AC9: 1 | AD9: 0 | AE9: 1 | AF9: 0 | AG9: 2 | AH9: 0 | AI9: 1 | AJ9: 0 | AK9: 2 | AL9: 1 | AM9: 2 | AN9: 0 | AO9: 2 | AP9: 0 | AQ9: 1 | AR9: 1 | AS9: 2 | AT9: 2 | AU9: 2 | AV9: 0 | AW9: 1 | AX9: 1 | AY9: 1 | AZ9: 2 | BA9: 2 | BB9: 1 | BC9: 1 | BD9: 0 | BE9: 2 | BF9: 1
B10: GA-M4: Mexico vs South Korea | C10: 2 | D10: 1 | E10: 1 | F10: 1 | G10: 3 | H10: 1 | I10: 1 | J10: 1 | K10: 1 | L10: 0 | M10: 2 | N10: 1 | O10: 2 | P10: 0 | Q10: 2 | R10: 1 | S10: 1 | T10: 1 | U10: 2 | V10: 2 | W10: 0 | X10: 0 | Y10: 1 | Z10: 2 | AA10: 1 | AB10: 1 | AC10: 2 | AD10: 2 | AE10: 2 | AF10: 1 | AG10: 2 | AH10: 1 | AI10: 2 | AJ10: 1 | AK10: 1 | AL10: 1 | AM10: 2 | AN10: 1 | AO10: 1 | AP10: 1 | AQ10: 2 | AR10: 1 | AS10: 1 | AT10: 0 | AU10: 1 | AV10: 1 | AW10: 1 | AX10: 0 | AY10: 2 | AZ10: 1 | BA10: 2 | BB10: 1 | BC10: 0 | BD10: 0 | BE10: 1 | BF10: 2
B11: GA-M5: Czech Rep. vs Mexico | C11: 1 | D11: 2 | E11: 0 | F11: 2 | G11: 1 | H11: 1 | I11: 1 | J11: 2 | K11: 1 | L11: 1 | M11: 1 | N11: 2 | O11: 1 | P11: 2 | Q11: 1 | R11: 2 | S11: 1 | T11: 2 | U11: 1 | V11: 2 | W11: 0 | X11: 2 | Y11: 1 | Z11: 1 | AA11: 0 | AB11: 1 | AC11: 1 | AD11: 1 | AE11: 1 | AF11: 1 | AG11: 1 | AH11: 1 | AI11: 1 | AJ11: 1 | AK11: 1 | AL11: 2 | AM11: 1 | AN11: 2 | AO11: 1 | AP11: 2 | AQ11: 1 | AR11: 2 | AS11: 3 | AT11: 2 | AU11: 1 | AV11: 2 | AW11: 2 | AX11: 1 | AY11: 0 | AZ11: 1 | BA11: 1 | BB11: 2 | BC11: 0 | BD11: 3 | BE11: 0 | BF11: 2
B12: GA-M6: South Africa vs South Korea | C12: 1 | D12: 2 | E12: 0 | F12: 2 | G12: 0 | H12: 2 | I12: 1 | J12: 2 | K12: 1 | L12: 2 | M12: 1 | N12: 2 | O12: 2 | P12: 2 | Q12: 0 | R12: 2 | S12: 0 | T12: 2 | U12: 0 | V12: 2 | W12: 1 | X12: 3 | Y12: 1 | Z12: 2 | AA12: 1 | AB12: 2 | AC12: 0 | AD12: 0 | AE12: 0 | AF12: 1 | AG12: 1 | AH12: 2 | AI12: 1 | AJ12: 1 | AK12: 0 | AL12: 1 | AM12: 0 | AN12: 2 | AO12: 0 | AP12: 2 | AQ12: 1 | AR12: 2 | AS12: 0 | AT12: 0 | AU12: 1 | AV12: 2 | AW12: 2 | AX12: 2 | AY12: 3 | AZ12: 1 | BA12: 1 | BB12: 2 | BC12: 1 | BD12: 3 | BE12: 1 | BF12: 2
B13: GB-M1: Canada vs Bosnia-Herz. | C13: 2 | D13: 0 | E13: 2 | F13: 1 | G13: 2 | H13: 0 | I13: 2 | J13: 0 | K13: 2 | L13: 1 | M13: 2 | N13: 1 | O13: 2 | P13: 2 | Q13: 2 | R13: 0 | S13: 1 | T13: 0 | U13: 1 | V13: 1 | W13: 3 | X13: 0 | Y13: 1 | Z13: 1 | AA13: 2 | AB13: 1 | AC13: 1 | AD13: 2 | AE13: 1 | AF13: 1 | AG13: 2 | AH13: 1 | AI13: 2 | AJ13: 0 | AK13: 2 | AL13: 1 | AM13: 2 | AN13: 1 | AO13: 1 | AP13: 1 | AQ13: 2 | AR13: 1 | AS13: 1 | AT13: 0 | AU13: 1 | AV13: 1 | AW13: 0 | AX13: 0 | AY13: 1 | AZ13: 1 | BA13: 2 | BB13: 0 | BC13: 1 | BD13: 0 | BE13: 2 | BF13: 1
B14: GB-M2: Qatar vs Switzerland | C14: 0 | D14: 2 | E14: 1 | F14: 2 | G14: 0 | H14: 2 | I14: 0 | J14: 3 | K14: 0 | L14: 3 | M14: 1 | N14: 2 | O14: 2 | P14: 1 | Q14: 0 | R14: 2 | S14: 0 | T14: 2 | U14: 0 | V14: 2 | W14: 0 | X14: 2 | Y14: 0 | Z14: 2 | AA14: 0 | AB14: 2 | AC14: 1 | AD14: 2 | AE14: 0 | AF14: 2 | AG14: 0 | AH14: 2 | AI14: 0 | AJ14: 3 | AK14: 0 | AL14: 2 | AM14: 0 | AN14: 2 | AO14: 0 | AP14: 2 | AQ14: 0 | AR14: 2 | AS14: 0 | AT14: 2 | AU14: 0 | AV14: 2 | AW14: 1 | AX14: 1 | AY14: 0 | AZ14: 3 | BA14: 0 | BB14: 2 | BC14: 0 | BD14: 2 | BE14: 0 | BF14: 2
B15: GB-M3: Switzerland vs Bosnia-Herz. | C15: 1 | D15: 1 | E15: 2 | F15: 0 | G15: 1 | H15: 0 | I15: 1 | J15: 0 | K15: 2 | L15: 0 | M15: 2 | N15: 1 | O15: 2 | P15: 0 | Q15: 2 | R15: 0 | S15: 2 | T15: 1 | U15: 2 | V15: 0 | W15: 2 | X15: 0 | Y15: 2 | Z15: 1 | AA15: 2 | AB15: 1 | AC15: 3 | AD15: 2 | AE15: 2 | AF15: 0 | AG15: 3 | AH15: 1 | AI15: 2 | AJ15: 1 | AK15: 2 | AL15: 1 | AM15: 2 | AN15: 0 | AO15: 2 | AP15: 1 | AQ15: 3 | AR15: 0 | AS15: 2 | AT15: 1 | AU15: 2 | AV15: 1 | AW15: 2 | AX15: 1 | AY15: 2 | AZ15: 0 | BA15: 2 | BB15: 0 | BC15: 3 | BD15: 1 | BE15: 3 | BF15: 1
B16: GB-M4: Canada vs Qatar | C16: 2 | D16: 1 | E16: 2 | F16: 1 | G16: 2 | H16: 1 | I16: 2 | J16: 0 | K16: 2 | L16: 0 | M16: 2 | N16: 1 | O16: 1 | P16: 1 | Q16: 2 | R16: 0 | S16: 2 | T16: 0 | U16: 2 | V16: 0 | W16: 2 | X16: 0 | Y16: 1 | Z16: 0 | AA16: 3 | AB16: 1 | AC16: 2 | AD16: 1 | AE16: 2 | AF16: 0 | AG16: 2 | AH16: 1 | AI16: 3 | AJ16: 1 | AK16: 2 | AL16: 0 | AM16: 2 | AN16: 0 | AO16: 2 | AP16: 0 | AQ16: 2 | AR16: 0 | AS16: 3 | AT16: 0 | AU16: 2 | AV16: 0 | AW16: 2 | AX16: 3 | AY16: 1 | AZ16: 0 | BA16: 1 | BB16: 1 | BC16: 0 | BD16: 1 | BE16: 3 | BF16: 0
B17: GB-M5: Switzerland vs Canada | C17: 1 | D17: 1 | E17: 1 | F17: 1 | G17: 1 | H17: 0 | I17: 2 | J17: 1 | K17: 2 | L17: 0 | M17: 2 | N17: 1 | O17: 1 | P17: 1 | Q17: 1 | R17: 1 | S17: 1 | T17: 1 | U17: 1 | V17: 1 | W17: 1 | X17: 0 | Y17: 2 | Z17: 0 | AA17: 1 | AB17: 1 | AC17: 1 | AD17: 1 | AE17: 1 | AF17: 1 | AG17: 1 | AH17: 1 | AI17: 2 | AJ17: 1 | AK17: 2 | AL17: 1 | AM17: 1 | AN17: 1 | AO17: 1 | AP17: 1 | AQ17: 1 | AR17: 1 | AS17: 1 | AT17: 1 | AU17: 1 | AV17: 1 | AW17: 1 | AX17: 1 | AY17: 1 | AZ17: 1 | BA17: 2 | BB17: 0 | BC17: 3 | BD17: 2 | BE17: 1 | BF17: 2
B18: GB-M6: Bosnia-Herz. vs Qatar | C18: 2 | D18: 1 | E18: 2 | F18: 1 | G18: 1 | H18: 2 | I18: 1 | J18: 0 | K18: 2 | L18: 1 | M18: 2 | N18: 1 | O18: 0 | P18: 2 | Q18: 2 | R18: 1 | S18: 2 | T18: 0 | U18: 2 | V18: 1 | W18: 1 | X18: 1 | Y18: 2 | Z18: 1 | AA18: 2 | AB18: 0 | AC18: 1 | AD18: 0 | AE18: 2 | AF18: 1 | AG18: 2 | AH18: 2 | AI18: 0 | AJ18: 0 | AK18: 1 | AL18: 0 | AM18: 2 | AN18: 1 | AO18: 1 | AP18: 0 | AQ18: 2 | AR18: 1 | AS18: 1 | AT18: 0 | AU18: 2 | AV18: 0 | AW18: 1 | AX18: 2 | AY18: 2 | AZ18: 1 | BA18: 1 | BB18: 1 | BC18: 1 | BD18: 1 | BE18: 2 | BF18: 1
... B78: GL-M6: Panama vs England | C78: 0 | D78: 4 | E78: 0 | F78: 2 | G78: 0 | H78: 3 | I78: 0 | J78: 3 | K78: 0 | L78: 3 | M78: 1 | N78: 2 | O78: 1 | P78: 5 | Q78: 0 | R78: 2 | S78: 0 | T78: 2 | U78: 0 | V78: 3 | W78: 0 | X78: 2 | Y78: 0 | Z78: 4 | AA78: 0 | AB78: 2 | AC78: 1 | AD78: 2 | AE78: 0 | AF78: 3 | AG78: 0 | AH78: 3 | AI78: 0 | AJ78: 3 | AK78: 0 | AL78: 5 | AM78: 0 | AN78: 3 | AO78: 1 | AP78: 2 | AQ78: 0 | AR78: 3 | AS78: 1 | AT78: 2 | AU78: 0 | AV78: 3 | AW78: 1 | AX78: 1 | AY78: 0 | AZ78: 4 | BA78: 0 | BB78: 3 | BC78: 1 | BD78: 3 | BE78: 0 | BF78: 3
B79: GROUP STANDINGS
B80: 1st group A | C80: Mexico | E80: Mexico | G80: Mexico | I80: Mexico | K80: Mexico | M80: Mexico | O80: Mexico | Q80: Mexico | S80: Mexico | U80: Mexico | W80: South Korea | Y80: South Korea | AA80: Mexico | AC80: Czech Rep. | AE80: Mexico | AG80: Mexico | AI80: Czech Rep. | AK80: Mexico | AM80: Mexico | AO80: Mexico | AQ80: Mexico | AS80: Mexico | AU80: Mexico | AW80: Mexico | AY80: Mexico | BA80: Mexico | BC80: Mexico | BE80: South Korea
B81: 2nd group A | C81: Czech Rep. | E81: South Korea | G81: Czech Rep. | I81: South Korea | K81: Czech Rep. | M81: South Korea | O81: South Korea | Q81: South Korea | S81: South Korea | U81: South Korea | W81: Mexico | Y81: Czech Rep. | AA81: South Korea | AC81: Mexico | AE81: Czech Rep. | AG81: South Korea | AI81: Mexico | AK81: South Korea | AM81: South Korea | AO81: South Korea | AQ81: South Korea | AS81: Czech Rep. | AU81: South Korea | AW81: Czech Rep. | AY81: South Africa | BA81: South Korea | BC81: South Korea | BE81: Mexico
B82: 3rd group A | C82: South Korea | E82: Czech Rep. | G82: South Korea | I82: Czech Rep. | K82: South Korea | M82: Czech Rep. | O82: Czech Rep. | Q82: Czech Rep. | S82: Czech Rep. | U82: Czech Rep. | W82: South Africa | Y82: Mexico | AA82: Czech Rep. | AC82: South Korea | AE82: South Korea | AG82: Czech Rep. | AI82: South Africa | AK82: Czech Rep. | AM82: Czech Rep. | AO82: Czech Rep. | AQ82: Czech Rep. | AS82: South Africa | AU82: Czech Rep. | AW82: South Africa | AY82: South Korea | BA82: Czech Rep. | BC82: Czech Rep. | BE82: Czech Rep.
B83: 1st group B | C83: Canada | E83: Switzerland | G83: Switzerland | I83: Switzerland | K83: Switzerland | M83: Switzerland | O83: Qatar | Q83: Canada | S83: Switzerland | U83: Switzerland | W83: Switzerland | Y83: Switzerland | AA83: Canada | AC83: Switzerland | AE83: Switzerland | AG83: Switzerland | AI83: Switzerland | AK83: Switzerland | AM83: Switzerland | AO83: Switzerland | AQ83: Switzerland | AS83: Canada | AU83: Switzerland | AW83: Qatar | AY83: Switzerland | BA83: Switzerland | BC83: Switzerland | BE83: Canada
B84: 2nd group B | C84: Switzerland | E84: Canada | G84: Canada | I84: Canada | K84: Canada | M84: Canada | O84: Switzerland | Q84: Switzerland | S84: Canada | U84: Canada | W84: Canada | Y84: Bosnia-Herz. | AA84: Switzerland | AC84: Bosnia-Herz. | AE84: Canada | AG84: Canada | AI84: Canada | AK84: Canada | AM84: Canada | AO84: Canada | AQ84: Canada | AS84: Switzerland | AU84: Canada | AW84: Switzerland | AY84: Canada | BA84: Canada | BC84: Qatar | BE84: Switzerland
B85: 3rd group B | C85: Bosnia-Herz. | E85: Bosnia-Herz. | G85: Qatar | I85: Bosnia-Herz. | K85: Bosnia-Herz. | M85: Bosnia-Herz. | O85: Canada | Q85: Bosnia-Herz. | S85: Bosnia-Herz. | U85: Bosnia-Herz. | W85: Qatar | Y85: Canada | AA85: Bosnia-Herz. | AC85: Canada | AE85: Bosnia-Herz. | AG85: Bosnia-Herz. | AI85: Bosnia-Herz. | AK85: Bosnia-Herz. | AM85: Bosnia-Herz. | AO85: Bosnia-Herz. | AQ85: Bosnia-Herz. | AS85: Bosnia-Herz. | AU85: Bosnia-Herz. | AW85: Canada | AY85: Bosnia-Herz. | BA85: Qatar | BC85: Canada | BE85: Bosnia-Herz.
B86: 1st group C | C86: Brazil | E86: Brazil | G86: Brazil | I86: Morocco | K86: Brazil | M86: Brazil | O86: Brazil | Q86: Brazil | S86: Brazil | U86: Brazil | W86: Brazil | Y86: Morocco | AA86: Brazil | AC86: Brazil | AE86: Brazil | AG86: Brazil | AI86: Brazil | AK86: Brazil | AM86: Brazil | AO86: Brazil | AQ86: Brazil | AS86: Morocco | AU86: Brazil | AW86: Scotland | AY86: Brazil | BA86: Brazil | BC86: Brazil | BE86: Brazil
B87: 2nd group C | C87: Morocco | E87: Morocco | G87: Morocco | I87: Brazil | K87: Scotland | M87: Morocco | O87: Morocco | Q87: Morocco | S87: Morocco | U87: Morocco | W87: Morocco | Y87: Brazil | AA87: Morocco | AC87: Morocco | AE87: Morocco | AG87: Morocco | AI87: Morocco | AK87: Morocco | AM87: Scotland | AO87: Morocco | AQ87: Morocco | AS87: Brazil | AU87: Morocco | AW87: Brazil | AY87: Morocco | BA87: Morocco | BC87: Morocco | BE87: Morocco
B88: 3rd group C | C88: Scotland | E88: Scotland | G88: Scotland | I88: Scotland | K88: Morocco | M88: Scotland | O88: Scotland | Q88: Scotland | S88: Scotland | U88: Scotland | W88: Scotland | Y88: Scotland | AA88: Scotland | AC88: Scotland | AE88: Scotland | AG88: Scotland | AI88: Haiti | AK88: Scotland | AM88: Morocco | AO88: Scotland | AQ88: Scotland | AS88: Scotland | AU88: Scotland | AW88: Morocco | AY88: Scotland | BA88: Scotland | BC88: Scotland | BE88: Scotland
B89: 1st group D | C89: USA | E89: Turkey | G89: Turkey | I89: Turkey | K89: Turkey | M89: USA | O89: Turkey | Q89: Turkey | S89: USA | U89: Turkey | W89: Turkey | Y89: Turkey | AA89: USA | AC89: Australia | AE89: USA | AG89: Turkey | AI89: USA | AK89: Turkey | AM89: USA | AO89: USA | AQ89: USA | AS89: Turkey | AU89: USA | AW89: Paraguay | AY89: Turkey | BA89: Turkey | BC89: Turkey | BE89: USA
B90: 2nd group D | C90: Turkey | E90: USA | G90: USA | I90: USA | K90: USA | M90: Turkey | O90: Paraguay | Q90: USA | S90: Paraguay | U90: USA | W90: USA | Y90: USA | AA90: Turkey | AC90: Paraguay | AE90: Turkey | AG90: USA | AI90: Turkey | AK90: USA | AM90: Turkey | AO90: Turkey | AQ90: Paraguay | AS90: USA | AU90: Turkey | AW90: Australia | AY90: Paraguay | BA90: Australia | BC90: USA | BE90: Turkey
B91: 3rd group D | C91: Paraguay | E91: Paraguay | G91: Australia | I91: Paraguay | K91: Australia | M91: Paraguay | O91: USA | Q91: Australia | S91: Australia | U91: Paraguay | W91: Australia | Y91: Paraguay | AA91: Paraguay | AC91: USA | AE91: Paraguay | AG91: Paraguay | AI91: Paraguay | AK91: Paraguay | AM91: Australia | AO91: Paraguay | AQ91: Turkey | AS91: Paraguay | AU91: Paraguay | AW91: Turkey | AY91: USA | BA91: USA | BC91: Paraguay | BE91: Paraguay
... B115: 3rd group L | C115: Ghana | E115: Ghana | G115: Ghana | I115: Ghana | K115: Ghana | M115: Ghana | O115: Ghana | Q115: Panama | S115: Panama | U115: Ghana | W115: Ghana | Y115: Ghana | AA115: Ghana | AC115: Ghana | AE115: Ghana | AG115: Ghana | AI115: Ghana | AK115: Croatia | AM115: Ghana | AO115: Ghana | AQ115: Ghana | AS115: Panama | AU115: Ghana | AW115: England | AY115: Ghana | BA115: Ghana | BC115: Ghana | BE115: Ghana
B116: 8 BEST THIRDS
B117: 3-1 | C117: South Korea | E117: Scotland | G117: Argentina | I117: Ivory Coast | K117: Ghana | M117: Czech Rep. | O117: USA | Q117: Ivory Coast | S117: Ecuador | U117: Ecuador | W117: Ivory Coast | Y117: Paraguay | AA117: Ecuador | AC117: Canada | AE117: Ecuador | AG117: Norway | AI117: Ghana | AK117: Ivory Coast | AM117: Czech Rep. | AO117: Czech Rep. | AQ117: Turkey | AS117: Scotland | AU117: Czech Rep. | AW117: Curacao | AY117: Bosnia-Herz. | BA117: Scotland | BC117: Paraguay | BE117: Sweden
B118: 3-2 | C118: Ivory Coast | E118: Iran | G118: South Korea | I118: Czech Rep. | K118: Japan | M118: Bosnia-Herz. | O118: Ghana | Q118: Senegal | S118: Norway | U118: Japan | W118: Iran | Y118: Colombia | AA118: Algeria | AC118: USA | AE118: Senegal | AG118: Czech Rep. | AI118: Austria | AK118: Scotland | AM118: Ivory Coast | AO118: Senegal | AQ118: Senegal | AS118: Sweden | AU118: Bosnia-Herz. | AW118: Austria | AY118: Senegal | BA118: Ivory Coast | BC118: Algeria | BE118: Ghana
B119: 3-3 | C119: Norway | E119: Senegal | G119: Ivory Coast | I119: Norway | K119: Morocco | M119: Scotland | O119: Canada | Q119: Algeria | S119: Bosnia-Herz. | U119: Scotland | W119: Algeria | Y119: Canada | AA119: Senegal | AC119: Egypt | AE119: South Korea | AG119: Japan | AI119: Paraguay | AK119: Czech Rep. | AM119: Senegal | AO119: Ivory Coast | AQ119: Scotland | AS119: Jordan | AU119: Scotland | AW119: Spain | AY119: South Korea | BA119: Czech Rep. | BC119: Cape Verde | BE119: Czech Rep.
B120: 3-4 | C120: Bosnia-Herz. | E120: Czech Rep. | G120: Saudi Arabia | I120: Scotland | K120: Ecuador | M120: Paraguay | O120: Scotland | Q120: Iran | S120: Scotland | U120: Senegal | W120: Sweden | Y120: Scotland | AA120: Czech Rep. | AC120: Scotland | AE120: Scotland | AG120: Saudi Arabia | AI120: Haiti | AK120: Bosnia-Herz. | AM120: Algeria | AO120: Bosnia-Herz. | AQ120: New Zealand | AS120: Bosnia-Herz. | AU120: Paraguay | AW120: England | AY120: USA | BA120: Tunisia | BC120: Czech Rep. | BE120: Scotland
B121: 3-5 | C121: Iran | E121: Algeria | G121: Iran | I121: Paraguay | K121: Norway | M121: Ivory Coast | O121: Saudi Arabia | Q121: Czech Rep. | S121: Saudi Arabia | U121: Algeria | W121: Scotland | Y121: Algeria | AA121: Iran | AC121: Saudi Arabia | AE121: Paraguay | AG121: Austria | AI121: Ecuador | AK121: Senegal | AM121: Ghana | AO121: Egypt | AQ121: Ivory Coast | AS121: Saudi Arabia | AU121: Ivory Coast | AW121: Turkey | AY121: DR Congo | BA121: Senegal | BC121: Ecuador | BE121: Ecuador
B122: 3-6 | C122: Scotland | E122: Ivory Coast | G122: Ghana | I122: Algeria | K122: South Korea | M122: Japan | O122: Ivory Coast | Q122: Scotland | S122: Panama | U122: Ghana | W122: Australia | Y122: Ghana | AA122: Bosnia-Herz. | AC122: Japan | AE122: Sweden | AG122: Paraguay | AI122: DR Congo | AK122: Croatia | AM122: Bosnia-Herz. | AO122: Algeria | AQ122: Japan | AS122: DR Congo | AU122: Japan | AW122: South Africa | AY122: Ghana | BA122: Cape Verde | BC122: Egypt | BE122: Senegal
B123: 3-7 | C123: Ghana | E123: Sweden | G123: Uzbekistan | I123: Japan | K123: Algeria | M123: Iran | O123: Senegal | Q123: Japan | S123: Czech Rep. | U123: Bosnia-Herz. | W123: Senegal | Y123: Ivory Coast | AA123: Paraguay | AC123: Ghana | AE123: Egypt | AG123: Ghana | AI123: Cape Verde | AK123: Algeria | AM123: Morocco | AO123: Sweden | AQ123: Bosnia-Herz. | AS123: Panama | AU123: Senegal | AW123: Canada | AY123: Sweden | BA123: USA | BC123: Scotland | BE123: Bosnia-Herz.
B124: 3-8 | C124: Japan | E124: Bosnia-Herz. | G124: Scotland | I124: Bosnia-Herz. | K124: Bosnia-Herz. | M124: Saudi Arabia | O124: Czech Rep. | Q124: Bosnia-Herz. | S124: Australia | U124: Iran | W124: Ghana | Y124: Mexico | AA124: Sweden | AC124: Jordan | AE124: Algeria | AG124: Scotland | AI124: Senegal | AK124: DR Congo | AM124: New Zealand | AO124: Ghana | AQ124: Czech Rep. | AS124: South Africa | AU124: Ghana | AW124: Sweden | AY124: Scotland | BA124: Qatar | BC124: Sweden | BE124: Algeria
...

Sheet Calculation
B2: POINTS CALCULATION (automatic)
B5: CONCEPT | C5: ='Raw data'!C6 -> Matt | E5: ='Raw data'!E6 -> Fer | G5: ='Raw data'!G6 -> Pano | I5: ='Raw data'!I6 -> Tere | K5: ='Raw data'!K6 -> Nadia | M5: ='Raw data'!M6 -> Jose | O5: ='Raw data'!O6 -> Lucía | Q5: ='Raw data'!Q6 -> Kike | S5: ='Raw data'!S6 -> Paibol | U5: ='Raw data'!U6 -> Pablo | W5: ='Raw data'!W6 -> Almu | Y5: ='Raw data'!Y6 -> Juanorro | AA5: ='Raw data'!AA6 -> Cillian | AC5: ='Raw data'!AC6 -> July | AE5: ='Raw data'!AE6 -> Toño | AG5: ='Raw data'!AG6 -> Juanin | AI5: ='Raw data'!AI6 -> Meg | AK5: ='Raw data'!AK6 -> Irene | AM5: ='Raw data'!AM6 -> Andy | AO5: ='Raw data'!AO6 -> Adri | AQ5: ='Raw data'!AQ6 -> Ben | AS5: ='Raw data'!AS6 -> Gon | AU5: ='Raw data'!AU6 -> Mile | AW5: ='Raw data'!AW6 -> Cami | AY5: ='Raw data'!AY6 -> Hugo | BA5: ='Raw data'!BA6 -> Jaime | BC5: ='Raw data'!BC6 -> Emilio | BE5: ='Raw data'!BE6 -> Manu | BG5: ='Raw data'!BG6 | BI5: ='Raw data'!BI6
B7: GROUP STAGE MATCHES
B8: GA-M1: Mexico vs South Africa | C8: =IFERROR(IF(AND(ISNUMBER('Real results'!C7),ISNUMBER('Real results'!D7),ISNUMBER('Raw data'!C7),ISNUMBER('Raw data'!D7)),IF(SIGN('Raw data'!C7-'Raw data'!D7)=SIGN('Real results'!C7-'Real results'!D7),2+IF(AND('Raw data'!C7='Real results'!C7,'Raw data'!D7='Real results'!D7),2,0),0),0),0) -> 0 | E8: =IFERROR(IF(AND(ISNUMBER('Real results'!C7),ISNUMBER('Real results'!D7),ISNUMBER('Raw data'!E7),ISNUMBER('Raw data'!F7)),IF(SIGN('Raw data'!E7-'Raw data'!F7)=SIGN('Real results'!C7-'Real results'!D7),2+IF(AND('Raw data'!E7='Real results'!C7,'Raw data'!F7='Real results'!D7),2,0),0),0),0) -> 0 | G8: =IFERROR(IF(AND(ISNUMBER('Real results'!C7),ISNUMBER('Real results'!D7),ISNUMBER('Raw data'!G7),ISNUMBER('Raw data'!H7)),IF(SIGN('Raw data'!G7-'Raw data'!H7)=SIGN('Real results'!C7-'Real results'!D7),2+IF(AND('Raw data'!G7='Real results'!C7,'Raw data'!H7='Real results'!D7),2,0),0),0),0) -> 0 | I8: =IFERROR(IF(AND(ISNUMBER('Real results'!C7),ISNUMBER('Real results'!D7),ISNUMBER('Raw data'!I7),ISNUMBER('Raw data'!J7)),IF(SIGN('Raw data'!I7-'Raw data'!J7)=SIGN('Real results'!C7-'Real results'!D7),2+IF(AND('Raw data'!I7='Real results'!C7,'Raw data'!J7='Real results'!D7),2,0),0),0),0) -> 0 | K8: =IFERROR(IF(AND(ISNUMBER('Real results'!C7),ISNUMBER('Real results'!D7),ISNUMBER('Raw data'!K7),ISNUMBER('Raw data'!L7)),IF(SIGN('Raw data'!K7-'Raw data'!L7)=SIGN('Real results'!C7-'Real results'!D7),2+IF(AND('Raw data'!K7='Real results'!C7,'Raw data'!L7='Real results'!D7),2,0),0),0),0) -> 0 | M8: =IFERROR(IF(AND(ISNUMBER('Real results'!C7),ISNUMBER('Real results'!D7),ISNUMBER('Raw data'!M7),ISNUMBER('Raw data'!N7)),IF(SIGN('Raw data'!M7-'Raw data'!N7)=SIGN('Real results'!C7-'Real results'!D7),2+IF(AND('Raw data'!M7='Real results'!C7,'Raw data'!N7='Real results'!D7),2,0),0),0),0) -> 0 | O8: =IFERROR(IF(AND(ISNUMBER('Real results'!C7),ISNUMBER('Real results'!D7),ISNUMBER('Raw data'!O7),ISNUMBER('Raw data'!P7)),IF(SIGN('Raw data'!O7-'Raw data'!P7)=SIGN('Real results'!C7-'Real results'!D7),2+IF(AND('Raw data'!O7='Real results'!C7,'Raw data'!P7='Real results'!D7),2,0),0),0),0) -> 0 | Q8: =IFERROR(IF(AND(ISNUMBER('Real results'!C7),ISNUMBER('Real results'!D7),ISNUMBER('Raw data'!Q7),ISNUMBER('Raw data'!R7)),IF(SIGN('Raw data'!Q7-'Raw data'!R7)=SIGN('Real results'!C7-'Real results'!D7),2+IF(AND('Raw data'!Q7='Real results'!C7,'Raw data'!R7='Real results'!D7),2,0),0),0),0) -> 0 | S8: =IFERROR(IF(AND(ISNUMBER('Real results'!C7),ISNUMBER('Real results'!D7),ISNUMBER('Raw data'!S7),ISNUMBER('Raw data'!T7)),IF(SIGN('Raw data'!S7-'Raw data'!T7)=SIGN('Real results'!C7-'Real results'!D7),2+IF(AND('Raw data'!S7='Real results'!C7,'Raw data'!T7='Real results'!D7),2,0),0),0),0) -> 0 | U8: =IFERROR(IF(AND(ISNUMBER('Real results'!C7),ISNUMBER('Real results'!D7),ISNUMBER('Raw data'!U7),ISNUMBER('Raw data'!V7)),IF(SIGN('Raw data'!U7-'Raw data'!V7)=SIGN('Real results'!C7-'Real results'!D7),2+IF(AND('Raw data'!U7='Real results'!C7,'Raw data'!V7='Real results'!D7),2,0),0),0),0) -> 0 | W8: =IFERROR(IF(AND(ISNUMBER('Real results'!C7),ISNUMBER('Real results'!D7),ISNUMBER('Raw data'!W7),ISNUMBER('Raw data'!X7)),IF(SIGN('Raw data'!W7-'Raw data'!X7)=SIGN('Real results'!C7-'Real results'!D7),2+IF(AND('Raw data'!W7='Real results'!C7,'Raw data'!X7='Real results'!D7),2,0),0),0),0) -> 0 | Y8: =IFERROR(IF(AND(ISNUMBER('Real results'!C7),ISNUMBER('Real results'!D7),ISNUMBER('Raw data'!Y7),ISNUMBER('Raw data'!Z7)),IF(SIGN('Raw data'!Y7-'Raw data'!Z7)=SIGN('Real results'!C7-'Real results'!D7),2+IF(AND('Raw data'!Y7='Real results'!C7,'Raw data'!Z7='Real results'!D7),2,0),0),0),0) -> 0 | AA8: =IFERROR(IF(AND(ISNUMBER('Real results'!C7),ISNUMBER('Real results'!D7),ISNUMBER('Raw data'!AA7),ISNUMBER('Raw data'!AB7)),IF(SIGN('Raw data'!AA7-'Raw data'!AB7)=SIGN('Real results'!C7-'Real results'!D7),2+IF(AND('Raw data'!AA7='Real results'!C7,'Raw data'!AB7='Real results'!D7),2,0),0),0),0) -> 0 | AC8: =IFERROR(IF(AND(ISNUMBER('Real results'!C7),ISNUMBER('Real results'!D7),ISNUMBER('Raw data'!AC7),ISNUMBER('Raw data'!AD7)),IF(SIGN('Raw data'!AC7-'Raw data'!AD7)=SIGN('Real results'!C7-'Real results'!D7),2+IF(AND('Raw data'!AC7='Real results'!C7,'Raw data'!AD7='Real results'!D7),2,0),0),0),0) -> 0 | AE8: =IFERROR(IF(AND(ISNUMBER('Real results'!C7),ISNUMBER('Real results'!D7),ISNUMBER('Raw data'!AE7),ISNUMBER('Raw data'!AF7)),IF(SIGN('Raw data'!AE7-'Raw data'!AF7)=SIGN('Real results'!C7-'Real results'!D7),2+IF(AND('Raw data'!AE7='Real results'!C7,'Raw data'!AF7='Real results'!D7),2,0),0),0),0) -> 0 | AG8: =IFERROR(IF(AND(ISNUMBER('Real results'!C7),ISNUMBER('Real results'!D7),ISNUMBER('Raw data'!AG7),ISNUMBER('Raw data'!AH7)),IF(SIGN('Raw data'!AG7-'Raw data'!AH7)=SIGN('Real results'!C7-'Real results'!D7),2+IF(AND('Raw data'!AG7='Real results'!C7,'Raw data'!AH7='Real results'!D7),2,0),0),0),0) -> 0 | AI8: =IFERROR(IF(AND(ISNUMBER('Real results'!C7),ISNUMBER('Real results'!D7),ISNUMBER('Raw data'!AI7),ISNUMBER('Raw data'!AJ7)),IF(SIGN('Raw data'!AI7-'Raw data'!AJ7)=SIGN('Real results'!C7-'Real results'!D7),2+IF(AND('Raw data'!AI7='Real results'!C7,'Raw data'!AJ7='Real results'!D7),2,0),0),0),0) -> 0 | AK8: =IFERROR(IF(AND(ISNUMBER('Real results'!C7),ISNUMBER('Real results'!D7),ISNUMBER('Raw data'!AK7),ISNUMBER('Raw data'!AL7)),IF(SIGN('Raw data'!AK7-'Raw data'!AL7)=SIGN('Real results'!C7-'Real results'!D7),2+IF(AND('Raw data'!AK7='Real results'!C7,'Raw data'!AL7='Real results'!D7),2,0),0),0),0) -> 0 | AM8: =IFERROR(IF(AND(ISNUMBER('Real results'!C7),ISNUMBER('Real results'!D7),ISNUMBER('Raw data'!AM7),ISNUMBER('Raw data'!AN7)),IF(SIGN('Raw data'!AM7-'Raw data'!AN7)=SIGN('Real results'!C7-'Real results'!D7),2+IF(AND('Raw data'!AM7='Real results'!C7,'Raw data'!AN7='Real results'!D7),2,0),0),0),0) -> 0 | AO8: =IFERROR(IF(AND(ISNUMBER('Real results'!C7),ISNUMBER('Real results'!D7),ISNUMBER('Raw data'!AO7),ISNUMBER('Raw data'!AP7)),IF(SIGN('Raw data'!AO7-'Raw data'!AP7)=SIGN('Real results'!C7-'Real results'!D7),2+IF(AND('Raw data'!AO7='Real results'!C7,'Raw data'!AP7='Real results'!D7),2,0),0),0),0) -> 0 | AQ8: =IFERROR(IF(AND(ISNUMBER('Real results'!C7),ISNUMBER('Real results'!D7),ISNUMBER('Raw data'!AQ7),ISNUMBER('Raw data'!AR7)),IF(SIGN('Raw data'!AQ7-'Raw data'!AR7)=SIGN('Real results'!C7-'Real results'!D7),2+IF(AND('Raw data'!AQ7='Real results'!C7,'Raw data'!AR7='Real results'!D7),2,0),0),0),0) -> 0 | AS8: =IFERROR(IF(AND(ISNUMBER('Real results'!C7),ISNUMBER('Real results'!D7),ISNUMBER('Raw data'!AS7),ISNUMBER('Raw data'!AT7)),IF(SIGN('Raw data'!AS7-'Raw data'!AT7)=SIGN('Real results'!C7-'Real results'!D7),2+IF(AND('Raw data'!AS7='Real results'!C7,'Raw data'!AT7='Real results'!D7),2,0),0),0),0) -> 0 | AU8: =IFERROR(IF(AND(ISNUMBER('Real results'!C7),ISNUMBER('Real results'!D7),ISNUMBER('Raw data'!AU7),ISNUMBER('Raw data'!AV7)),IF(SIGN('Raw data'!AU7-'Raw data'!AV7)=SIGN('Real results'!C7-'Real results'!D7),2+IF(AND('Raw data'!AU7='Real results'!C7,'Raw data'!AV7='Real results'!D7),2,0),0),0),0) -> 0 | AW8: =IFERROR(IF(AND(ISNUMBER('Real results'!C7),ISNUMBER('Real results'!D7),ISNUMBER('Raw data'!AW7),ISNUMBER('Raw data'!AX7)),IF(SIGN('Raw data'!AW7-'Raw data'!AX7)=SIGN('Real results'!C7-'Real results'!D7),2+IF(AND('Raw data'!AW7='Real results'!C7,'Raw data'!AX7='Real results'!D7),2,0),0),0),0) -> 0 | AY8: =IFERROR(IF(AND(ISNUMBER('Real results'!C7),ISNUMBER('Real results'!D7),ISNUMBER('Raw data'!AY7),ISNUMBER('Raw data'!AZ7)),IF(SIGN('Raw data'!AY7-'Raw data'!AZ7)=SIGN('Real results'!C7-'Real results'!D7),2+IF(AND('Raw data'!AY7='Real results'!C7,'Raw data'!AZ7='Real results'!D7),2,0),0),0),0) -> 0 | BA8: =IFERROR(IF(AND(ISNUMBER('Real results'!C7),ISNUMBER('Real results'!D7),ISNUMBER('Raw data'!BA7),ISNUMBER('Raw data'!BB7)),IF(SIGN('Raw data'!BA7-'Raw data'!BB7)=SIGN('Real results'!C7-'Real results'!D7),2+IF(AND('Raw data'!BA7='Real results'!C7,'Raw data'!BB7='Real results'!D7),2,0),0),0),0) -> 0 | BC8: =IFERROR(IF(AND(ISNUMBER('Real results'!C7),ISNUMBER('Real results'!D7),ISNUMBER('Raw data'!BC7),ISNUMBER('Raw data'!BD7)),IF(SIGN('Raw data'!BC7-'Raw data'!BD7)=SIGN('Real results'!C7-'Real results'!D7),2+IF(AND('Raw data'!BC7='Real results'!C7,'Raw data'!BD7='Real results'!D7),2,0),0),0),0) -> 0 | BE8: =IFERROR(IF(AND(ISNUMBER('Real results'!C7),ISNUMBER('Real results'!D7),ISNUMBER('Raw data'!BE7),ISNUMBER('Raw data'!BF7)),IF(SIGN('Raw data'!BE7-'Raw data'!BF7)=SIGN('Real results'!C7-'Real results'!D7),2+IF(AND('Raw data'!BE7='Real results'!C7,'Raw data'!BF7='Real results'!D7),2,0),0),0),0) -> 0 | BG8: =IFERROR(IF(AND(ISNUMBER('Real results'!C7),ISNUMBER('Real results'!D7),ISNUMBER('Raw data'!BG7),ISNUMBER('Raw data'!BH7)),IF(SIGN('Raw data'!BG7-'Raw data'!BH7)=SIGN('Real results'!C7-'Real results'!D7),2+IF(AND('Raw data'!BG7='Real results'!C7,'Raw data'!BH7='Real results'!D7),2,0),0),0),0) -> 0 | BI8: =IFERROR(IF(AND(ISNUMBER('Real results'!C7),ISNUMBER('Real results'!D7),ISNUMBER('Raw data'!BI7),ISNUMBER('Raw data'!BJ7)),IF(SIGN('Raw data'!BI7-'Raw data'!BJ7)=SIGN('Real results'!C7-'Real results'!D7),2+IF(AND('Raw data'!BI7='Real results'!C7,'Raw data'!BJ7='Real results'!D7),2,0),0),0),0) -> 0
B9: GA-M2: South Korea vs Czech Rep. | C9: =IFERROR(IF(AND(ISNUMBER('Real results'!C8),ISNUMBER('Real results'!D8),ISNUMBER('Raw data'!C8),ISNUMBER('Raw data'!D8)),IF(SIGN('Raw data'!C8-'Raw data'!D8)=SIGN('Real results'!C8-'Real results'!D8),2+IF(AND('Raw data'!C8='Real results'!C8,'Raw data'!D8='Real results'!D8),2,0),0),0),0) -> 0 | E9: =IFERROR(IF(AND(ISNUMBER('Real results'!C8),ISNUMBER('Real results'!D8),ISNUMBER('Raw data'!E8),ISNUMBER('Raw data'!F8)),IF(SIGN('Raw data'!E8-'Raw data'!F8)=SIGN('Real results'!C8-'Real results'!D8),2+IF(AND('Raw data'!E8='Real results'!C8,'Raw data'!F8='Real results'!D8),2,0),0),0),0) -> 0 | G9: =IFERROR(IF(AND(ISNUMBER('Real results'!C8),ISNUMBER('Real results'!D8),ISNUMBER('Raw data'!G8),ISNUMBER('Raw data'!H8)),IF(SIGN('Raw data'!G8-'Raw data'!H8)=SIGN('Real results'!C8-'Real results'!D8),2+IF(AND('Raw data'!G8='Real results'!C8,'Raw data'!H8='Real results'!D8),2,0),0),0),0) -> 0 | I9: =IFERROR(IF(AND(ISNUMBER('Real results'!C8),ISNUMBER('Real results'!D8),ISNUMBER('Raw data'!I8),ISNUMBER('Raw data'!J8)),IF(SIGN('Raw data'!I8-'Raw data'!J8)=SIGN('Real results'!C8-'Real results'!D8),2+IF(AND('Raw data'!I8='Real results'!C8,'Raw data'!J8='Real results'!D8),2,0),0),0),0) -> 0 | K9: =IFERROR(IF(AND(ISNUMBER('Real results'!C8),ISNUMBER('Real results'!D8),ISNUMBER('Raw data'!K8),ISNUMBER('Raw data'!L8)),IF(SIGN('Raw data'!K8-'Raw data'!L8)=SIGN('Real results'!C8-'Real results'!D8),2+IF(AND('Raw data'!K8='Real results'!C8,'Raw data'!L8='Real results'!D8),2,0),0),0),0) -> 0 | M9: =IFERROR(IF(AND(ISNUMBER('Real results'!C8),ISNUMBER('Real results'!D8),ISNUMBER('Raw data'!M8),ISNUMBER('Raw data'!N8)),IF(SIGN('Raw data'!M8-'Raw data'!N8)=SIGN('Real results'!C8-'Real results'!D8),2+IF(AND('Raw data'!M8='Real results'!C8,'Raw data'!N8='Real results'!D8),2,0),0),0),0) -> 0 | O9: =IFERROR(IF(AND(ISNUMBER('Real results'!C8),ISNUMBER('Real results'!D8),ISNUMBER('Raw data'!O8),ISNUMBER('Raw data'!P8)),IF(SIGN('Raw data'!O8-'Raw data'!P8)=SIGN('Real results'!C8-'Real results'!D8),2+IF(AND('Raw data'!O8='Real results'!C8,'Raw data'!P8='Real results'!D8),2,0),0),0),0) -> 0 | Q9: =IFERROR(IF(AND(ISNUMBER('Real results'!C8),ISNUMBER('Real results'!D8),ISNUMBER('Raw data'!Q8),ISNUMBER('Raw data'!R8)),IF(SIGN('Raw data'!Q8-'Raw data'!R8)=SIGN('Real results'!C8-'Real results'!D8),2+IF(AND('Raw data'!Q8='Real results'!C8,'Raw data'!R8='Real results'!D8),2,0),0),0),0) -> 0 | S9: =IFERROR(IF(AND(ISNUMBER('Real results'!C8),ISNUMBER('Real results'!D8),ISNUMBER('Raw data'!S8),ISNUMBER('Raw data'!T8)),IF(SIGN('Raw data'!S8-'Raw data'!T8)=SIGN('Real results'!C8-'Real results'!D8),2+IF(AND('Raw data'!S8='Real results'!C8,'Raw data'!T8='Real results'!D8),2,0),0),0),0) -> 0 | U9: =IFERROR(IF(AND(ISNUMBER('Real results'!C8),ISNUMBER('Real results'!D8),ISNUMBER('Raw data'!U8),ISNUMBER('Raw data'!V8)),IF(SIGN('Raw data'!U8-'Raw data'!V8)=SIGN('Real results'!C8-'Real results'!D8),2+IF(AND('Raw data'!U8='Real results'!C8,'Raw data'!V8='Real results'!D8),2,0),0),0),0) -> 0 | W9: =IFERROR(IF(AND(ISNUMBER('Real results'!C8),ISNUMBER('Real results'!D8),ISNUMBER('Raw data'!W8),ISNUMBER('Raw data'!X8)),IF(SIGN('Raw data'!W8-'Raw data'!X8)=SIGN('Real results'!C8-'Real results'!D8),2+IF(AND('Raw data'!W8='Real results'!C8,'Raw data'!X8='Real results'!D8),2,0),0),0),0) -> 0 | Y9: =IFERROR(IF(AND(ISNUMBER('Real results'!C8),ISNUMBER('Real results'!D8),ISNUMBER('Raw data'!Y8),ISNUMBER('Raw data'!Z8)),IF(SIGN('Raw data'!Y8-'Raw data'!Z8)=SIGN('Real results'!C8-'Real results'!D8),2+IF(AND('Raw data'!Y8='Real results'!C8,'Raw data'!Z8='Real results'!D8),2,0),0),0),0) -> 0 | AA9: =IFERROR(IF(AND(ISNUMBER('Real results'!C8),ISNUMBER('Real results'!D8),ISNUMBER('Raw data'!AA8),ISNUMBER('Raw data'!AB8)),IF(SIGN('Raw data'!AA8-'Raw data'!AB8)=SIGN('Real results'!C8-'Real results'!D8),2+IF(AND('Raw data'!AA8='Real results'!C8,'Raw data'!AB8='Real results'!D8),2,0),0),0),0) -> 0 | AC9: =IFERROR(IF(AND(ISNUMBER('Real results'!C8),ISNUMBER('Real results'!D8),ISNUMBER('Raw data'!AC8),ISNUMBER('Raw data'!AD8)),IF(SIGN('Raw data'!AC8-'Raw data'!AD8)=SIGN('Real results'!C8-'Real results'!D8),2+IF(AND('Raw data'!AC8='Real results'!C8,'Raw data'!AD8='Real results'!D8),2,0),0),0),0) -> 0 | AE9: =IFERROR(IF(AND(ISNUMBER('Real results'!C8),ISNUMBER('Real results'!D8),ISNUMBER('Raw data'!AE8),ISNUMBER('Raw data'!AF8)),IF(SIGN('Raw data'!AE8-'Raw data'!AF8)=SIGN('Real results'!C8-'Real results'!D8),2+IF(AND('Raw data'!AE8='Real results'!C8,'Raw data'!AF8='Real results'!D8),2,0),0),0),0) -> 0 | AG9: =IFERROR(IF(AND(ISNUMBER('Real results'!C8),ISNUMBER('Real results'!D8),ISNUMBER('Raw data'!AG8),ISNUMBER('Raw data'!AH8)),IF(SIGN('Raw data'!AG8-'Raw data'!AH8)=SIGN('Real results'!C8-'Real results'!D8),2+IF(AND('Raw data'!AG8='Real results'!C8,'Raw data'!AH8='Real results'!D8),2,0),0),0),0) -> 0 | AI9: =IFERROR(IF(AND(ISNUMBER('Real results'!C8),ISNUMBER('Real results'!D8),ISNUMBER('Raw data'!AI8),ISNUMBER('Raw data'!AJ8)),IF(SIGN('Raw data'!AI8-'Raw data'!AJ8)=SIGN('Real results'!C8-'Real results'!D8),2+IF(AND('Raw data'!AI8='Real results'!C8,'Raw data'!AJ8='Real results'!D8),2,0),0),0),0) -> 0 | AK9: =IFERROR(IF(AND(ISNUMBER('Real results'!C8),ISNUMBER('Real results'!D8),ISNUMBER('Raw data'!AK8),ISNUMBER('Raw data'!AL8)),IF(SIGN('Raw data'!AK8-'Raw data'!AL8)=SIGN('Real results'!C8-'Real results'!D8),2+IF(AND('Raw data'!AK8='Real results'!C8,'Raw data'!AL8='Real results'!D8),2,0),0),0),0) -> 0 | AM9: =IFERROR(IF(AND(ISNUMBER('Real results'!C8),ISNUMBER('Real results'!D8),ISNUMBER('Raw data'!AM8),ISNUMBER('Raw data'!AN8)),IF(SIGN('Raw data'!AM8-'Raw data'!AN8)=SIGN('Real results'!C8-'Real results'!D8),2+IF(AND('Raw data'!AM8='Real results'!C8,'Raw data'!AN8='Real results'!D8),2,0),0),0),0) -> 0 | AO9: =IFERROR(IF(AND(ISNUMBER('Real results'!C8),ISNUMBER('Real results'!D8),ISNUMBER('Raw data'!AO8),ISNUMBER('Raw data'!AP8)),IF(SIGN('Raw data'!AO8-'Raw data'!AP8)=SIGN('Real results'!C8-'Real results'!D8),2+IF(AND('Raw data'!AO8='Real results'!C8,'Raw data'!AP8='Real results'!D8),2,0),0),0),0) -> 0 | AQ9: =IFERROR(IF(AND(ISNUMBER('Real results'!C8),ISNUMBER('Real results'!D8),ISNUMBER('Raw data'!AQ8),ISNUMBER('Raw data'!AR8)),IF(SIGN('Raw data'!AQ8-'Raw data'!AR8)=SIGN('Real results'!C8-'Real results'!D8),2+IF(AND('Raw data'!AQ8='Real results'!C8,'Raw data'!AR8='Real results'!D8),2,0),0),0),0) -> 0 | AS9: =IFERROR(IF(AND(ISNUMBER('Real results'!C8),ISNUMBER('Real results'!D8),ISNUMBER('Raw data'!AS8),ISNUMBER('Raw data'!AT8)),IF(SIGN('Raw data'!AS8-'Raw data'!AT8)=SIGN('Real results'!C8-'Real results'!D8),2+IF(AND('Raw data'!AS8='Real results'!C8,'Raw data'!AT8='Real results'!D8),2,0),0),0),0) -> 0 | AU9: =IFERROR(IF(AND(ISNUMBER('Real results'!C8),ISNUMBER('Real results'!D8),ISNUMBER('Raw data'!AU8),ISNUMBER('Raw data'!AV8)),IF(SIGN('Raw data'!AU8-'Raw data'!AV8)=SIGN('Real results'!C8-'Real results'!D8),2+IF(AND('Raw data'!AU8='Real results'!C8,'Raw data'!AV8='Real results'!D8),2,0),0),0),0) -> 0 | AW9: =IFERROR(IF(AND(ISNUMBER('Real results'!C8),ISNUMBER('Real results'!D8),ISNUMBER('Raw data'!AW8),ISNUMBER('Raw data'!AX8)),IF(SIGN('Raw data'!AW8-'Raw data'!AX8)=SIGN('Real results'!C8-'Real results'!D8),2+IF(AND('Raw data'!AW8='Real results'!C8,'Raw data'!AX8='Real results'!D8),2,0),0),0),0) -> 0 | AY9: =IFERROR(IF(AND(ISNUMBER('Real results'!C8),ISNUMBER('Real results'!D8),ISNUMBER('Raw data'!AY8),ISNUMBER('Raw data'!AZ8)),IF(SIGN('Raw data'!AY8-'Raw data'!AZ8)=SIGN('Real results'!C8-'Real results'!D8),2+IF(AND('Raw data'!AY8='Real results'!C8,'Raw data'!AZ8='Real results'!D8),2,0),0),0),0) -> 0 | BA9: =IFERROR(IF(AND(ISNUMBER('Real results'!C8),ISNUMBER('Real results'!D8),ISNUMBER('Raw data'!BA8),ISNUMBER('Raw data'!BB8)),IF(SIGN('Raw data'!BA8-'Raw data'!BB8)=SIGN('Real results'!C8-'Real results'!D8),2+IF(AND('Raw data'!BA8='Real results'!C8,'Raw data'!BB8='Real results'!D8),2,0),0),0),0) -> 0 | BC9: =IFERROR(IF(AND(ISNUMBER('Real results'!C8),ISNUMBER('Real results'!D8),ISNUMBER('Raw data'!BC8),ISNUMBER('Raw data'!BD8)),IF(SIGN('Raw data'!BC8-'Raw data'!BD8)=SIGN('Real results'!C8-'Real results'!D8),2+IF(AND('Raw data'!BC8='Real results'!C8,'Raw data'!BD8='Real results'!D8),2,0),0),0),0) -> 0 | BE9: =IFERROR(IF(AND(ISNUMBER('Real results'!C8),ISNUMBER('Real results'!D8),ISNUMBER('Raw data'!BE8),ISNUMBER('Raw data'!BF8)),IF(SIGN('Raw data'!BE8-'Raw data'!BF8)=SIGN('Real results'!C8-'Real results'!D8),2+IF(AND('Raw data'!BE8='Real results'!C8,'Raw data'!BF8='Real results'!D8),2,0),0),0),0) -> 0 | BG9: =IFERROR(IF(AND(ISNUMBER('Real results'!C8),ISNUMBER('Real results'!D8),ISNUMBER('Raw data'!BG8),ISNUMBER('Raw data'!BH8)),IF(SIGN('Raw data'!BG8-'Raw data'!BH8)=SIGN('Real results'!C8-'Real results'!D8),2+IF(AND('Raw data'!BG8='Real results'!C8,'Raw data'!BH8='Real results'!D8),2,0),0),0),0) -> 0 | BI9: =IFERROR(IF(AND(ISNUMBER('Real results'!C8),ISNUMBER('Real results'!D8),ISNUMBER('Raw data'!BI8),ISNUMBER('Raw data'!BJ8)),IF(SIGN('Raw data'!BI8-'Raw data'!BJ8)=SIGN('Real results'!C8-'Real results'!D8),2+IF(AND('Raw data'!BI8='Real results'!C8,'Raw data'!BJ8='Real results'!D8),2,0),0),0),0) -> 0
B10: GA-M3: Czech Rep. vs South Africa | C10: =IFERROR(IF(AND(ISNUMBER('Real results'!C9),ISNUMBER('Real results'!D9),ISNUMBER('Raw data'!C9),ISNUMBER('Raw data'!D9)),IF(SIGN('Raw data'!C9-'Raw data'!D9)=SIGN('Real results'!C9-'Real results'!D9),2+IF(AND('Raw data'!C9='Real results'!C9,'Raw data'!D9='Real results'!D9),2,0),0),0),0) -> 0 | E10: =IFERROR(IF(AND(ISNUMBER('Real results'!C9),ISNUMBER('Real results'!D9),ISNUMBER('Raw data'!E9),ISNUMBER('Raw data'!F9)),IF(SIGN('Raw data'!E9-'Raw data'!F9)=SIGN('Real results'!C9-'Real results'!D9),2+IF(AND('Raw data'!E9='Real results'!C9,'Raw data'!F9='Real results'!D9),2,0),0),0),0) -> 0 | G10: =IFERROR(IF(AND(ISNUMBER('Real results'!C9),ISNUMBER('Real results'!D9),ISNUMBER('Raw data'!G9),ISNUMBER('Raw data'!H9)),IF(SIGN('Raw data'!G9-'Raw data'!H9)=SIGN('Real results'!C9-'Real results'!D9),2+IF(AND('Raw data'!G9='Real results'!C9,'Raw data'!H9='Real results'!D9),2,0),0),0),0) -> 0 | I10: =IFERROR(IF(AND(ISNUMBER('Real results'!C9),ISNUMBER('Real results'!D9),ISNUMBER('Raw data'!I9),ISNUMBER('Raw data'!J9)),IF(SIGN('Raw data'!I9-'Raw data'!J9)=SIGN('Real results'!C9-'Real results'!D9),2+IF(AND('Raw data'!I9='Real results'!C9,'Raw data'!J9='Real results'!D9),2,0),0),0),0) -> 0 | K10: =IFERROR(IF(AND(ISNUMBER('Real results'!C9),ISNUMBER('Real results'!D9),ISNUMBER('Raw data'!K9),ISNUMBER('Raw data'!L9)),IF(SIGN('Raw data'!K9-'Raw data'!L9)=SIGN('Real results'!C9-'Real results'!D9),2+IF(AND('Raw data'!K9='Real results'!C9,'Raw data'!L9='Real results'!D9),2,0),0),0),0) -> 0 | M10: =IFERROR(IF(AND(ISNUMBER('Real results'!C9),ISNUMBER('Real results'!D9),ISNUMBER('Raw data'!M9),ISNUMBER('Raw data'!N9)),IF(SIGN('Raw data'!M9-'Raw data'!N9)=SIGN('Real results'!C9-'Real results'!D9),2+IF(AND('Raw data'!M9='Real results'!C9,'Raw data'!N9='Real results'!D9),2,0),0),0),0) -> 0 | O10: =IFERROR(IF(AND(ISNUMBER('Real results'!C9),ISNUMBER('Real results'!D9),ISNUMBER('Raw data'!O9),ISNUMBER('Raw data'!P9)),IF(SIGN('Raw data'!O9-'Raw data'!P9)=SIGN('Real results'!C9-'Real results'!D9),2+IF(AND('Raw data'!O9='Real results'!C9,'Raw data'!P9='Real results'!D9),2,0),0),0),0) -> 0 | Q10: =IFERROR(IF(AND(ISNUMBER('Real results'!C9),ISNUMBER('Real results'!D9),ISNUMBER('Raw data'!Q9),ISNUMBER('Raw data'!R9)),IF(SIGN('Raw data'!Q9-'Raw data'!R9)=SIGN('Real results'!C9-'Real results'!D9),2+IF(AND('Raw data'!Q9='Real results'!C9,'Raw data'!R9='Real results'!D9),2,0),0),0),0) -> 0 | S10: =IFERROR(IF(AND(ISNUMBER('Real results'!C9),ISNUMBER('Real results'!D9),ISNUMBER('Raw data'!S9),ISNUMBER('Raw data'!T9)),IF(SIGN('Raw data'!S9-'Raw data'!T9)=SIGN('Real results'!C9-'Real results'!D9),2+IF(AND('Raw data'!S9='Real results'!C9,'Raw data'!T9='Real results'!D9),2,0),0),0),0) -> 0 | U10: =IFERROR(IF(AND(ISNUMBER('Real results'!C9),ISNUMBER('Real results'!D9),ISNUMBER('Raw data'!U9),ISNUMBER('Raw data'!V9)),IF(SIGN('Raw data'!U9-'Raw data'!V9)=SIGN('Real results'!C9-'Real results'!D9),2+IF(AND('Raw data'!U9='Real results'!C9,'Raw data'!V9='Real results'!D9),2,0),0),0),0) -> 0 | W10: =IFERROR(IF(AND(ISNUMBER('Real results'!C9),ISNUMBER('Real results'!D9),ISNUMBER('Raw data'!W9),ISNUMBER('Raw data'!X9)),IF(SIGN('Raw data'!W9-'Raw data'!X9)=SIGN('Real results'!C9-'Real results'!D9),2+IF(AND('Raw data'!W9='Real results'!C9,'Raw data'!X9='Real results'!D9),2,0),0),0),0) -> 0 | Y10: =IFERROR(IF(AND(ISNUMBER('Real results'!C9),ISNUMBER('Real results'!D9),ISNUMBER('Raw data'!Y9),ISNUMBER('Raw data'!Z9)),IF(SIGN('Raw data'!Y9-'Raw data'!Z9)=SIGN('Real results'!C9-'Real results'!D9),2+IF(AND('Raw data'!Y9='Real results'!C9,'Raw data'!Z9='Real results'!D9),2,0),0),0),0) -> 0 | AA10: =IFERROR(IF(AND(ISNUMBER('Real results'!C9),ISNUMBER('Real results'!D9),ISNUMBER('Raw data'!AA9),ISNUMBER('Raw data'!AB9)),IF(SIGN('Raw data'!AA9-'Raw data'!AB9)=SIGN('Real results'!C9-'Real results'!D9),2+IF(AND('Raw data'!AA9='Real results'!C9,'Raw data'!AB9='Real results'!D9),2,0),0),0),0) -> 0 | AC10: =IFERROR(IF(AND(ISNUMBER('Real results'!C9),ISNUMBER('Real results'!D9),ISNUMBER('Raw data'!AC9),ISNUMBER('Raw data'!AD9)),IF(SIGN('Raw data'!AC9-'Raw data'!AD9)=SIGN('Real results'!C9-'Real results'!D9),2+IF(AND('Raw data'!AC9='Real results'!C9,'Raw data'!AD9='Real results'!D9),2,0),0),0),0) -> 0 | AE10: =IFERROR(IF(AND(ISNUMBER('Real results'!C9),ISNUMBER('Real results'!D9),ISNUMBER('Raw data'!AE9),ISNUMBER('Raw data'!AF9)),IF(SIGN('Raw data'!AE9-'Raw data'!AF9)=SIGN('Real results'!C9-'Real results'!D9),2+IF(AND('Raw data'!AE9='Real results'!C9,'Raw data'!AF9='Real results'!D9),2,0),0),0),0) -> 0 | AG10: =IFERROR(IF(AND(ISNUMBER('Real results'!C9),ISNUMBER('Real results'!D9),ISNUMBER('Raw data'!AG9),ISNUMBER('Raw data'!AH9)),IF(SIGN('Raw data'!AG9-'Raw data'!AH9)=SIGN('Real results'!C9-'Real results'!D9),2+IF(AND('Raw data'!AG9='Real results'!C9,'Raw data'!AH9='Real results'!D9),2,0),0),0),0) -> 0 | AI10: =IFERROR(IF(AND(ISNUMBER('Real results'!C9),ISNUMBER('Real results'!D9),ISNUMBER('Raw data'!AI9),ISNUMBER('Raw data'!AJ9)),IF(SIGN('Raw data'!AI9-'Raw data'!AJ9)=SIGN('Real results'!C9-'Real results'!D9),2+IF(AND('Raw data'!AI9='Real results'!C9,'Raw data'!AJ9='Real results'!D9),2,0),0),0),0) -> 0 | AK10: =IFERROR(IF(AND(ISNUMBER('Real results'!C9),ISNUMBER('Real results'!D9),ISNUMBER('Raw data'!AK9),ISNUMBER('Raw data'!AL9)),IF(SIGN('Raw data'!AK9-'Raw data'!AL9)=SIGN('Real results'!C9-'Real results'!D9),2+IF(AND('Raw data'!AK9='Real results'!C9,'Raw data'!AL9='Real results'!D9),2,0),0),0),0) -> 0 | AM10: =IFERROR(IF(AND(ISNUMBER('Real results'!C9),ISNUMBER('Real results'!D9),ISNUMBER('Raw data'!AM9),ISNUMBER('Raw data'!AN9)),IF(SIGN('Raw data'!AM9-'Raw data'!AN9)=SIGN('Real results'!C9-'Real results'!D9),2+IF(AND('Raw data'!AM9='Real results'!C9,'Raw data'!AN9='Real results'!D9),2,0),0),0),0) -> 0 | AO10: =IFERROR(IF(AND(ISNUMBER('Real results'!C9),ISNUMBER('Real results'!D9),ISNUMBER('Raw data'!AO9),ISNUMBER('Raw data'!AP9)),IF(SIGN('Raw data'!AO9-'Raw data'!AP9)=SIGN('Real results'!C9-'Real results'!D9),2+IF(AND('Raw data'!AO9='Real results'!C9,'Raw data'!AP9='Real results'!D9),2,0),0),0),0) -> 0 | AQ10: =IFERROR(IF(AND(ISNUMBER('Real results'!C9),ISNUMBER('Real results'!D9),ISNUMBER('Raw data'!AQ9),ISNUMBER('Raw data'!AR9)),IF(SIGN('Raw data'!AQ9-'Raw data'!AR9)=SIGN('Real results'!C9-'Real results'!D9),2+IF(AND('Raw data'!AQ9='Real results'!C9,'Raw data'!AR9='Real results'!D9),2,0),0),0),0) -> 0 | AS10: =IFERROR(IF(AND(ISNUMBER('Real results'!C9),ISNUMBER('Real results'!D9),ISNUMBER('Raw data'!AS9),ISNUMBER('Raw data'!AT9)),IF(SIGN('Raw data'!AS9-'Raw data'!AT9)=SIGN('Real results'!C9-'Real results'!D9),2+IF(AND('Raw data'!AS9='Real results'!C9,'Raw data'!AT9='Real results'!D9),2,0),0),0),0) -> 0 | AU10: =IFERROR(IF(AND(ISNUMBER('Real results'!C9),ISNUMBER('Real results'!D9),ISNUMBER('Raw data'!AU9),ISNUMBER('Raw data'!AV9)),IF(SIGN('Raw data'!AU9-'Raw data'!AV9)=SIGN('Real results'!C9-'Real results'!D9),2+IF(AND('Raw data'!AU9='Real results'!C9,'Raw data'!AV9='Real results'!D9),2,0),0),0),0) -> 0 | AW10: =IFERROR(IF(AND(ISNUMBER('Real results'!C9),ISNUMBER('Real results'!D9),ISNUMBER('Raw data'!AW9),ISNUMBER('Raw data'!AX9)),IF(SIGN('Raw data'!AW9-'Raw data'!AX9)=SIGN('Real results'!C9-'Real results'!D9),2+IF(AND('Raw data'!AW9='Real results'!C9,'Raw data'!AX9='Real results'!D9),2,0),0),0),0) -> 0 | AY10: =IFERROR(IF(AND(ISNUMBER('Real results'!C9),ISNUMBER('Real results'!D9),ISNUMBER('Raw data'!AY9),ISNUMBER('Raw data'!AZ9)),IF(SIGN('Raw data'!AY9-'Raw data'!AZ9)=SIGN('Real results'!C9-'Real results'!D9),2+IF(AND('Raw data'!AY9='Real results'!C9,'Raw data'!AZ9='Real results'!D9),2,0),0),0),0) -> 0 | BA10: =IFERROR(IF(AND(ISNUMBER('Real results'!C9),ISNUMBER('Real results'!D9),ISNUMBER('Raw data'!BA9),ISNUMBER('Raw data'!BB9)),IF(SIGN('Raw data'!BA9-'Raw data'!BB9)=SIGN('Real results'!C9-'Real results'!D9),2+IF(AND('Raw data'!BA9='Real results'!C9,'Raw data'!BB9='Real results'!D9),2,0),0),0),0) -> 0 | BC10: =IFERROR(IF(AND(ISNUMBER('Real results'!C9),ISNUMBER('Real results'!D9),ISNUMBER('Raw data'!BC9),ISNUMBER('Raw data'!BD9)),IF(SIGN('Raw data'!BC9-'Raw data'!BD9)=SIGN('Real results'!C9-'Real results'!D9),2+IF(AND('Raw data'!BC9='Real results'!C9,'Raw data'!BD9='Real results'!D9),2,0),0),0),0) -> 0 | BE10: =IFERROR(IF(AND(ISNUMBER('Real results'!C9),ISNUMBER('Real results'!D9),ISNUMBER('Raw data'!BE9),ISNUMBER('Raw data'!BF9)),IF(SIGN('Raw data'!BE9-'Raw data'!BF9)=SIGN('Real results'!C9-'Real results'!D9),2+IF(AND('Raw data'!BE9='Real results'!C9,'Raw data'!BF9='Real results'!D9),2,0),0),0),0) -> 0 | BG10: =IFERROR(IF(AND(ISNUMBER('Real results'!C9),ISNUMBER('Real results'!D9),ISNUMBER('Raw data'!BG9),ISNUMBER('Raw data'!BH9)),IF(SIGN('Raw data'!BG9-'Raw data'!BH9)=SIGN('Real results'!C9-'Real results'!D9),2+IF(AND('Raw data'!BG9='Real results'!C9,'Raw data'!BH9='Real results'!D9),2,0),0),0),0) -> 0 | BI10: =IFERROR(IF(AND(ISNUMBER('Real results'!C9),ISNUMBER('Real results'!D9),ISNUMBER('Raw data'!BI9),ISNUMBER('Raw data'!BJ9)),IF(SIGN('Raw data'!BI9-'Raw data'!BJ9)=SIGN('Real results'!C9-'Real results'!D9),2+IF(AND('Raw data'!BI9='Real results'!C9,'Raw data'!BJ9='Real results'!D9),2,0),0),0),0) -> 0
B11: GA-M4: Mexico vs South Korea | C11: =IFERROR(IF(AND(ISNUMBER('Real results'!C10),ISNUMBER('Real results'!D10),ISNUMBER('Raw data'!C10),ISNUMBER('Raw data'!D10)),IF(SIGN('Raw data'!C10-'Raw data'!D10)=SIGN('Real results'!C10-'Real results'!D10),2+IF(AND('Raw data'!C10='Real results'!C10,'Raw data'!D10='Real results'!D10),2,0),0),0),0) -> 0 | E11: =IFERROR(IF(AND(ISNUMBER('Real results'!C10),ISNUMBER('Real results'!D10),ISNUMBER('Raw data'!E10),ISNUMBER('Raw data'!F10)),IF(SIGN('Raw data'!E10-'Raw data'!F10)=SIGN('Real results'!C10-'Real results'!D10),2+IF(AND('Raw data'!E10='Real results'!C10,'Raw data'!F10='Real results'!D10),2,0),0),0),0) -> 0 | G11: =IFERROR(IF(AND(ISNUMBER('Real results'!C10),ISNUMBER('Real results'!D10),ISNUMBER('Raw data'!G10),ISNUMBER('Raw data'!H10)),IF(SIGN('Raw data'!G10-'Raw data'!H10)=SIGN('Real results'!C10-'Real results'!D10),2+IF(AND('Raw data'!G10='Real results'!C10,'Raw data'!H10='Real results'!D10),2,0),0),0),0) -> 0 | I11: =IFERROR(IF(AND(ISNUMBER('Real results'!C10),ISNUMBER('Real results'!D10),ISNUMBER('Raw data'!I10),ISNUMBER('Raw data'!J10)),IF(SIGN('Raw data'!I10-'Raw data'!J10)=SIGN('Real results'!C10-'Real results'!D10),2+IF(AND('Raw data'!I10='Real results'!C10,'Raw data'!J10='Real results'!D10),2,0),0),0),0) -> 0 | K11: =IFERROR(IF(AND(ISNUMBER('Real results'!C10),ISNUMBER('Real results'!D10),ISNUMBER('Raw data'!K10),ISNUMBER('Raw data'!L10)),IF(SIGN('Raw data'!K10-'Raw data'!L10)=SIGN('Real results'!C10-'Real results'!D10),2+IF(AND('Raw data'!K10='Real results'!C10,'Raw data'!L10='Real results'!D10),2,0),0),0),0) -> 0 | M11: =IFERROR(IF(AND(ISNUMBER('Real results'!C10),ISNUMBER('Real results'!D10),ISNUMBER('Raw data'!M10),ISNUMBER('Raw data'!N10)),IF(SIGN('Raw data'!M10-'Raw data'!N10)=SIGN('Real results'!C10-'Real results'!D10),2+IF(AND('Raw data'!M10='Real results'!C10,'Raw data'!N10='Real results'!D10),2,0),0),0),0) -> 0 | O11: =IFERROR(IF(AND(ISNUMBER('Real results'!C10),ISNUMBER('Real results'!D10),ISNUMBER('Raw data'!O10),ISNUMBER('Raw data'!P10)),IF(SIGN('Raw data'!O10-'Raw data'!P10)=SIGN('Real results'!C10-'Real results'!D10),2+IF(AND('Raw data'!O10='Real results'!C10,'Raw data'!P10='Real results'!D10),2,0),0),0),0) -> 0 | Q11: =IFERROR(IF(AND(ISNUMBER('Real results'!C10),ISNUMBER('Real results'!D10),ISNUMBER('Raw data'!Q10),ISNUMBER('Raw data'!R10)),IF(SIGN('Raw data'!Q10-'Raw data'!R10)=SIGN('Real results'!C10-'Real results'!D10),2+IF(AND('Raw data'!Q10='Real results'!C10,'Raw data'!R10='Real results'!D10),2,0),0),0),0) -> 0 | S11: =IFERROR(IF(AND(ISNUMBER('Real results'!C10),ISNUMBER('Real results'!D10),ISNUMBER('Raw data'!S10),ISNUMBER('Raw data'!T10)),IF(SIGN('Raw data'!S10-'Raw data'!T10)=SIGN('Real results'!C10-'Real results'!D10),2+IF(AND('Raw data'!S10='Real results'!C10,'Raw data'!T10='Real results'!D10),2,0),0),0),0) -> 0 | U11: =IFERROR(IF(AND(ISNUMBER('Real results'!C10),ISNUMBER('Real results'!D10),ISNUMBER('Raw data'!U10),ISNUMBER('Raw data'!V10)),IF(SIGN('Raw data'!U10-'Raw data'!V10)=SIGN('Real results'!C10-'Real results'!D10),2+IF(AND('Raw data'!U10='Real results'!C10,'Raw data'!V10='Real results'!D10),2,0),0),0),0) -> 0 | W11: =IFERROR(IF(AND(ISNUMBER('Real results'!C10),ISNUMBER('Real results'!D10),ISNUMBER('Raw data'!W10),ISNUMBER('Raw data'!X10)),IF(SIGN('Raw data'!W10-'Raw data'!X10)=SIGN('Real results'!C10-'Real results'!D10),2+IF(AND('Raw data'!W10='Real results'!C10,'Raw data'!X10='Real results'!D10),2,0),0),0),0) -> 0 | Y11: =IFERROR(IF(AND(ISNUMBER('Real results'!C10),ISNUMBER('Real results'!D10),ISNUMBER('Raw data'!Y10),ISNUMBER('Raw data'!Z10)),IF(SIGN('Raw data'!Y10-'Raw data'!Z10)=SIGN('Real results'!C10-'Real results'!D10),2+IF(AND('Raw data'!Y10='Real results'!C10,'Raw data'!Z10='Real results'!D10),2,0),0),0),0) -> 0 | AA11: =IFERROR(IF(AND(ISNUMBER('Real results'!C10),ISNUMBER('Real results'!D10),ISNUMBER('Raw data'!AA10),ISNUMBER('Raw data'!AB10)),IF(SIGN('Raw data'!AA10-'Raw data'!AB10)=SIGN('Real results'!C10-'Real results'!D10),2+IF(AND('Raw data'!AA10='Real results'!C10,'Raw data'!AB10='Real results'!D10),2,0),0),0),0) -> 0 | AC11: =IFERROR(IF(AND(ISNUMBER('Real results'!C10),ISNUMBER('Real results'!D10),ISNUMBER('Raw data'!AC10),ISNUMBER('Raw data'!AD10)),IF(SIGN('Raw data'!AC10-'Raw data'!AD10)=SIGN('Real results'!C10-'Real results'!D10),2+IF(AND('Raw data'!AC10='Real results'!C10,'Raw data'!AD10='Real results'!D10),2,0),0),0),0) -> 0 | AE11: =IFERROR(IF(AND(ISNUMBER('Real results'!C10),ISNUMBER('Real results'!D10),ISNUMBER('Raw data'!AE10),ISNUMBER('Raw data'!AF10)),IF(SIGN('Raw data'!AE10-'Raw data'!AF10)=SIGN('Real results'!C10-'Real results'!D10),2+IF(AND('Raw data'!AE10='Real results'!C10,'Raw data'!AF10='Real results'!D10),2,0),0),0),0) -> 0 | AG11: =IFERROR(IF(AND(ISNUMBER('Real results'!C10),ISNUMBER('Real results'!D10),ISNUMBER('Raw data'!AG10),ISNUMBER('Raw data'!AH10)),IF(SIGN('Raw data'!AG10-'Raw data'!AH10)=SIGN('Real results'!C10-'Real results'!D10),2+IF(AND('Raw data'!AG10='Real results'!C10,'Raw data'!AH10='Real results'!D10),2,0),0),0),0) -> 0 | AI11: =IFERROR(IF(AND(ISNUMBER('Real results'!C10),ISNUMBER('Real results'!D10),ISNUMBER('Raw data'!AI10),ISNUMBER('Raw data'!AJ10)),IF(SIGN('Raw data'!AI10-'Raw data'!AJ10)=SIGN('Real results'!C10-'Real results'!D10),2+IF(AND('Raw data'!AI10='Real results'!C10,'Raw data'!AJ10='Real results'!D10),2,0),0),0),0) -> 0 | AK11: =IFERROR(IF(AND(ISNUMBER('Real results'!C10),ISNUMBER('Real results'!D10),ISNUMBER('Raw data'!AK10),ISNUMBER('Raw data'!AL10)),IF(SIGN('Raw data'!AK10-'Raw data'!AL10)=SIGN('Real results'!C10-'Real results'!D10),2+IF(AND('Raw data'!AK10='Real results'!C10,'Raw data'!AL10='Real results'!D10),2,0),0),0),0) -> 0 | AM11: =IFERROR(IF(AND(ISNUMBER('Real results'!C10),ISNUMBER('Real results'!D10),ISNUMBER('Raw data'!AM10),ISNUMBER('Raw data'!AN10)),IF(SIGN('Raw data'!AM10-'Raw data'!AN10)=SIGN('Real results'!C10-'Real results'!D10),2+IF(AND('Raw data'!AM10='Real results'!C10,'Raw data'!AN10='Real results'!D10),2,0),0),0),0) -> 0 | AO11: =IFERROR(IF(AND(ISNUMBER('Real results'!C10),ISNUMBER('Real results'!D10),ISNUMBER('Raw data'!AO10),ISNUMBER('Raw data'!AP10)),IF(SIGN('Raw data'!AO10-'Raw data'!AP10)=SIGN('Real results'!C10-'Real results'!D10),2+IF(AND('Raw data'!AO10='Real results'!C10,'Raw data'!AP10='Real results'!D10),2,0),0),0),0) -> 0 | AQ11: =IFERROR(IF(AND(ISNUMBER('Real results'!C10),ISNUMBER('Real results'!D10),ISNUMBER('Raw data'!AQ10),ISNUMBER('Raw data'!AR10)),IF(SIGN('Raw data'!AQ10-'Raw data'!AR10)=SIGN('Real results'!C10-'Real results'!D10),2+IF(AND('Raw data'!AQ10='Real results'!C10,'Raw data'!AR10='Real results'!D10),2,0),0),0),0) -> 0 | AS11: =IFERROR(IF(AND(ISNUMBER('Real results'!C10),ISNUMBER('Real results'!D10),ISNUMBER('Raw data'!AS10),ISNUMBER('Raw data'!AT10)),IF(SIGN('Raw data'!AS10-'Raw data'!AT10)=SIGN('Real results'!C10-'Real results'!D10),2+IF(AND('Raw data'!AS10='Real results'!C10,'Raw data'!AT10='Real results'!D10),2,0),0),0),0) -> 0 | AU11: =IFERROR(IF(AND(ISNUMBER('Real results'!C10),ISNUMBER('Real results'!D10),ISNUMBER('Raw data'!AU10),ISNUMBER('Raw data'!AV10)),IF(SIGN('Raw data'!AU10-'Raw data'!AV10)=SIGN('Real results'!C10-'Real results'!D10),2+IF(AND('Raw data'!AU10='Real results'!C10,'Raw data'!AV10='Real results'!D10),2,0),0),0),0) -> 0 | AW11: =IFERROR(IF(AND(ISNUMBER('Real results'!C10),ISNUMBER('Real results'!D10),ISNUMBER('Raw data'!AW10),ISNUMBER('Raw data'!AX10)),IF(SIGN('Raw data'!AW10-'Raw data'!AX10)=SIGN('Real results'!C10-'Real results'!D10),2+IF(AND('Raw data'!AW10='Real results'!C10,'Raw data'!AX10='Real results'!D10),2,0),0),0),0) -> 0 | AY11: =IFERROR(IF(AND(ISNUMBER('Real results'!C10),ISNUMBER('Real results'!D10),ISNUMBER('Raw data'!AY10),ISNUMBER('Raw data'!AZ10)),IF(SIGN('Raw data'!AY10-'Raw data'!AZ10)=SIGN('Real results'!C10-'Real results'!D10),2+IF(AND('Raw data'!AY10='Real results'!C10,'Raw data'!AZ10='Real results'!D10),2,0),0),0),0) -> 0 | BA11: =IFERROR(IF(AND(ISNUMBER('Real results'!C10),ISNUMBER('Real results'!D10),ISNUMBER('Raw data'!BA10),ISNUMBER('Raw data'!BB10)),IF(SIGN('Raw data'!BA10-'Raw data'!BB10)=SIGN('Real results'!C10-'Real results'!D10),2+IF(AND('Raw data'!BA10='Real results'!C10,'Raw data'!BB10='Real results'!D10),2,0),0),0),0) -> 0 | BC11: =IFERROR(IF(AND(ISNUMBER('Real results'!C10),ISNUMBER('Real results'!D10),ISNUMBER('Raw data'!BC10),ISNUMBER('Raw data'!BD10)),IF(SIGN('Raw data'!BC10-'Raw data'!BD10)=SIGN('Real results'!C10-'Real results'!D10),2+IF(AND('Raw data'!BC10='Real results'!C10,'Raw data'!BD10='Real results'!D10),2,0),0),0),0) -> 0 | BE11: =IFERROR(IF(AND(ISNUMBER('Real results'!C10),ISNUMBER('Real results'!D10),ISNUMBER('Raw data'!BE10),ISNUMBER('Raw data'!BF10)),IF(SIGN('Raw data'!BE10-'Raw data'!BF10)=SIGN('Real results'!C10-'Real results'!D10),2+IF(AND('Raw data'!BE10='Real results'!C10,'Raw data'!BF10='Real results'!D10),2,0),0),0),0) -> 0 | BG11: =IFERROR(IF(AND(ISNUMBER('Real results'!C10),ISNUMBER('Real results'!D10),ISNUMBER('Raw data'!BG10),ISNUMBER('Raw data'!BH10)),IF(SIGN('Raw data'!BG10-'Raw data'!BH10)=SIGN('Real results'!C10-'Real results'!D10),2+IF(AND('Raw data'!BG10='Real results'!C10,'Raw data'!BH10='Real results'!D10),2,0),0),0),0) -> 0 | BI11: =IFERROR(IF(AND(ISNUMBER('Real results'!C10),ISNUMBER('Real results'!D10),ISNUMBER('Raw data'!BI10),ISNUMBER('Raw data'!BJ10)),IF(SIGN('Raw data'!BI10-'Raw data'!BJ10)=SIGN('Real results'!C10-'Real results'!D10),2+IF(AND('Raw data'!BI10='Real results'!C10,'Raw data'!BJ10='Real results'!D10),2,0),0),0),0) -> 0
