Workbook

Sheet Start
B2: WORLD CUP 2026 POOL - ADMIN
B6: WORKFLOW
B8: 1. Each participant sends you their file with the 'Admin export' tab filled in.
B9: 2. Open 'Raw data' and, for each participant, paste their Admin export columns C and D
B10: into the matching participant slot (P1, P2, ...). Each participant takes TWO columns:
B11: home goals + away goals (or value for non-score items).
B12: 3. Type the participant's real name in row 6 of the home column.
B13: 4. In 'Real results' fill in the actual match results as games are played.
B14: 5. 'Calculation' and 'Standings' tabs update automatically.
B16: WORKS FOR BOTH OPTIONS
B17: Option 1 (all-in-one) and Option 2 (groups + knockouts separated) use the same
B18: export format, so this admin handles both seamlessly.
... B32: • Top Scorer: 8 pts | Ballon d'Or: 8 pts

Sheet Real results
B2: REAL RESULTS
B3: Fill in the real results as matches are played. Score-type rows use two cells: Home and Away.
B5: Concept | C5: Home / Value | D5: Away
B6: GROUP STAGE SCORES
B7: GA-M1: Mexico vs South Africa | C7: 2 | D7: 0 | F7: GA-M1: Mexico vs South Africa | G7: 2 | H7: 0 | I7: =F7=B7 -> TRUE
B8: GA-M2: South Korea vs Czech Rep. | C8: 2 | D8: 1 | F8: GA-M2: South Korea vs Czech Rep. | G8: 2 | H8: 1 | I8: =F8=B8 -> TRUE
B9: GA-M3: Czech Rep. vs South Africa | C9: 1 | D9: 1 | F9: GA-M3: Czech Rep. vs South Africa | G9: 1 | H9: 1 | I9: =F9=B9 -> TRUE
B10: GA-M4: Mexico vs South Korea | C10: 1 | D10: 0 | F10: GA-M4: Mexico vs South Korea | G10: 1 | H10: 0 | I10: =F10=B10 -> TRUE
B11: GA-M5: Czech Rep. vs Mexico | C11: 0 | D11: 3 | F11: GA-M5: Czech Rep. vs Mexico | G11: 0 | H11: 3 | I11: =F11=B11 -> TRUE
B12: GA-M6: South Africa vs South Korea | C12: 1 | D12: 0 | F12: GA-M6: South Africa vs South Korea | G12: 1 | H12: 0 | I12: =F12=B12 -> TRUE
B13: GB-M1: Canada vs Bosnia-Herz. | C13: 1 | D13: 1 | F13: GB-M1: Canada vs Bosnia-Herz. | G13: 1 | H13: 1 | I13: =F13=B13 -> TRUE
B14: GB-M2: Qatar vs Switzerland | C14: 1 | D14: 1 | F14: GB-M2: Qatar vs Switzerland | G14: 1 | H14: 1 | I14: =F14=B14 -> TRUE
B15: GB-M3: Switzerland vs Bosnia-Herz. | C15: 4 | D15: 1 | F15: GB-M3: Switzerland vs Bosnia-Herz. | G15: 4 | H15: 1 | I15: =F15=B15 -> TRUE
B16: GB-M4: Canada vs Qatar | C16: 6 | D16: 0 | F16: GB-M4: Canada vs Qatar | G16: 6 | H16: 0 | I16: =F16=B16 -> TRUE
B17: GB-M5: Switzerland vs Canada | C17: 2 | D17: 1 | F17: GB-M5: Switzerland vs Canada | G17: 2 | H17: 1 | I17: =F17=B17 -> TRUE
B18: GB-M6: Bosnia-Herz. vs Qatar | C18: 3 | D18: 1 | F18: GB-M6: Bosnia-Herz. vs Qatar | G18: 3 | H18: 1 | I18: =F18=B18 -> TRUE
... B78: GL-M6: Panama vs England | C78: 0 | D78: 2 | F78: GL-M6: Panama vs England | G78: 0 | H78: 2 | I78: =F78=B78 -> TRUE
B79: GROUP STANDINGS
B80: 1st group A
B81: 2nd group A
B82: 3rd group A
B83: 1st group B
B84: 2nd group B
B85: 3rd group B
B86: 1st group C
B87: 2nd group C
B88: 3rd group C
B89: 1st group D
B90: 2nd group D
... B229: Ballon d'Or

Sheet Raw data
B2: RAW DATA - paste participant exports here
B3: Each participant takes TWO columns. Paste their 'Admin export' columns C and D into their slot. Row 6 holds their real name (in the Home column of each pair).
B5: CONCEPT | C5: P1 | E5: P2 | G5: P3 | I5: P4 | K5: P5 | M5: P6 | O5: P7 | Q5: P8 | S5: P9 | U5: P10 | W5: P11 | Y5: P12 | AA5: P13 | AC5: P14 | AE5: P15 | AG5: P16 | AI5: P17 | AK5: P18 | AM5: P19 | AO5: P20 | AQ5: P21 | AS5: P22 | AU5: P23 | AW5: P24 | AY5: P25 | BA5: P26 | BC5: P27 | BE5: P28 | BG5: P29 | BI5: P30
B6: GROUP STAGE SCORES | C6: Matt | E6: Fer | G6: Pano | I6: Tere | K6: Jose
B7: GA-M1: Mexico vs South Africa | C7: 2 | D7: 1 | E7: 2 | F7: 0 | G7: 3 | H7: 0 | I7: 3 | J7: 1 | K7: 2 | L7: 1
B8: GA-M2: South Korea vs Czech Rep. | C8: 1 | D8: 1 | E8: 1 | F8: 1 | G8: 1 | H8: 1 | I8: 2 | J8: 1 | K8: 2 | L8: 1
B9: GA-M3: Czech Rep. vs South Africa | C9: 2 | D9: 0 | E9: 1 | F9: 0 | G9: 1 | H9: 0 | I9: 2 | J9: 0 | K9: 2 | L9: 1
B10: GA-M4: Mexico vs South Korea | C10: 2 | D10: 1 | E10: 1 | F10: 1 | G10: 3 | H10: 1 | I10: 1 | J10: 1 | K10: 2 | L10: 1
B11: GA-M5: Czech Rep. vs Mexico | C11: 1 | D11: 2 | E11: 0 | F11: 2 | G11: 1 | H11: 1 | I11: 1 | J11: 2 | K11: 1 | L11: 2
B12: GA-M6: South Africa vs South Korea | C12: 1 | D12: 2 | E12: 0 | F12: 2 | G12: 0 | H12: 2 | I12: 1 | J12: 2 | K12: 1 | L12: 2
B13: GB-M1: Canada vs Bosnia-Herz. | C13: 2 | D13: 0 | E13: 2 | F13: 1 | G13: 2 | H13: 0 | I13: 2 | J13: 0 | K13: 2 | L13: 1
B14: GB-M2: Qatar vs Switzerland | C14: 0 | D14: 2 | E14: 1 | F14: 2 | G14: 0 | H14: 2 | I14: 0 | J14: 3 | K14: 1 | L14: 2
B15: GB-M3: Switzerland vs Bosnia-Herz. | C15: 1 | D15: 1 | E15: 2 | F15: 0 | G15: 1 | H15: 0 | I15: 1 | J15: 0 | K15: 2 | L15: 1
B16: GB-M4: Canada vs Qatar | C16: 2 | D16: 1 | E16: 2 | F16: 1 | G16: 2 | H16: 1 | I16: 2 | J16: 0 | K16: 2 | L16: 1
B17: GB-M5: Switzerland vs Canada | C17: 1 | D17: 1 | E17: 1 | F17: 1 | G17: 1 | H17: 0 | I17: 2 | J17: 1 | K17: 2 | L17: 1
B18: GB-M6: Bosnia-Herz. vs Qatar | C18: 2 | D18: 1 | E18: 2 | F18: 1 | G18: 1 | H18: 2 | I18: 1 | J18: 0 | K18: 2 | L18: 1
... B78: GL-M6: Panama vs England | C78: 0 | D78: 4 | E78: 0 | F78: 2 | G78: 0 | H78: 3 | I78: 0 | J78: 3 | K78: 1 | L78: 2
B79: GROUP STANDINGS
B80: 1st group A | C80: Mexico | E80: Mexico | G80: Mexico | I80: Mexico | K80: Mexico
B81: 2nd group A | C81: Czech Rep. | E81: South Korea | G81: Czech Rep. | I81: South Korea | K81: South Korea
B82: 3rd group A | C82: South Korea | E82: Czech Rep. | G82: South Korea | I82: Czech Rep. | K82: Czech Rep.
B83: 1st group B | C83: Canada | E83: Switzerland | G83: Switzerland | I83: Switzerland | K83: Switzerland
B84: 2nd group B | C84: Switzerland | E84: Canada | G84: Canada | I84: Canada | K84: Canada
B85: 3rd group B | C85: Bosnia-Herz. | E85: Bosnia-Herz. | G85: Qatar | I85: Bosnia-Herz. | K85: Bosnia-Herz.
B86: 1st group C | C86: Brazil | E86: Brazil | G86: Brazil | I86: Morocco | K86: Brazil
B87: 2nd group C | C87: Morocco | E87: Morocco | G87: Morocco | I87: Brazil | K87: Morocco
B88: 3rd group C | C88: Scotland | E88: Scotland | G88: Scotland | I88: Scotland | K88: Scotland
B89: 1st group D | C89: USA | E89: Turkey | G89: Turkey | I89: Turkey | K89: USA
B90: 2nd group D | C90: Turkey | E90: USA | G90: USA | I90: USA | K90: Turkey
B91: 3rd group D | C91: Paraguay | E91: Paraguay | G91: Australia | I91: Paraguay | K91: Paraguay
... B115: 3rd group L | C115: Ghana | E115: Ghana | G115: Ghana | I115: Ghana | K115: Ghana
B116: 8 BEST THIRDS
B117: 3-1 | C117: South Korea | E117: Scotland | G117: Argentina | I117: Ivory Coast | K117: Czech Rep.
B118: 3-2 | C118: Ivory Coast | E118: Iran | G118: South Korea | I118: Czech Rep. | K118: Bosnia-Herz.
B119: 3-3 | C119: Norway | E119: Senegal | G119: Ivory Coast | I119: Norway | K119: Scotland
B120: 3-4 | C120: Bosnia-Herz. | E120: Czech Rep. | G120: Saudi Arabia | I120: Scotland | K120: Paraguay
B121: 3-5 | C121: Iran | E121: Algeria | G121: Iran | I121: Paraguay | K121: Ivory Coast
B122: 3-6 | C122: Scotland | E122: Ivory Coast | G122: Ghana | I122: Algeria | K122: Japan
B123: 3-7 | C123: Ghana | E123: Bosnia-Herz. | G123: Uzbekistan | I123: Japan | K123: Iran
B124: 3-8 | C124: Japan | E124: Ghana | G124: Scotland | I124: Bosnia-Herz. | K124: Saudi Arabia
...

Sheet Calculation
B2: POINTS CALCULATION (automatic)
B5: CONCEPT | C5: ='Raw data'!C6 -> Matt | E5: ='Raw data'!E6 -> Fer | G5: ='Raw data'!G6 -> Pano | I5: ='Raw data'!I6 -> Tere | K5: JE | M5: ='Raw data'!M6 | O5: ='Raw data'!O6 | Q5: ='Raw data'!Q6 | S5: ='Raw data'!S6 | U5: ='Raw data'!U6 | W5: ='Raw data'!W6 | Y5: ='Raw data'!Y6 | AA5: ='Raw data'!AA6 | AC5: ='Raw data'!AC6 | AE5: ='Raw data'!AE6 | AG5: ='Raw data'!AG6 | AI5: ='Raw data'!AI6 | AK5: ='Raw data'!AK6 | AM5: ='Raw data'!AM6 | AO5: ='Raw data'!AO6 | AQ5: ='Raw data'!AQ6 | AS5: ='Raw data'!AS6 | AU5: ='Raw data'!AU6 | AW5: ='Raw data'!AW6 | AY5: ='Raw data'!AY6 | BA5: ='Raw data'!BA6 | BC5: ='Raw data'!BC6 | BE5: ='Raw data'!BE6 | BG5: ='Raw data'!BG6 | BI5: ='Raw data'!BI6
B7: GROUP STAGE MATCHES
B8: GA-M1: Mexico vs South Africa | C8: =IFERROR(IF(AND(ISNUMBER('Real results'!C7),ISNUMBER('Real results'!D7),ISNUMBER(#REF!),ISNUMBER(#REF!)),IF(SIGN(#REF!-#REF!)=SIGN('Real results'!C7-'Real results'!D7),2+IF(AND(#REF!='Real results'!C7,#REF!='Real results'!D7),2,0),0),0),0) -> 0 | E8: =IFERROR(IF(AND(ISNUMBER('Real results'!C7),ISNUMBER('Real results'!D7),ISNUMBER(#REF!),ISNUMBER(#REF!)),IF(SIGN(#REF!-#REF!)=SIGN('Real results'!C7-'Real results'!D7),2+IF(AND(#REF!='Real results'!C7,#REF!='Real results'!D7),2,0),0),0),0) -> 0 | G8: =IFERROR(IF(AND(ISNUMBER('Real results'!C7),ISNUMBER('Real results'!D7),ISNUMBER('Raw data'!G7),ISNUMBER('Raw data'!H7)),IF(SIGN('Raw data'!G7-'Raw data'!H7)=SIGN('Real results'!C7-'Real results'!D7),2+IF(AND('Raw data'!G7='Real results'!C7,'Raw data'!H7='Real results'!D7),2,0),0),0),0) -> 2 | I8: =IFERROR(IF(AND(ISNUMBER('Real results'!C7),ISNUMBER('Real results'!D7),ISNUMBER('Raw data'!I7),ISNUMBER('Raw data'!J7)),IF(SIGN('Raw data'!I7-'Raw data'!J7)=SIGN('Real results'!C7-'Real results'!D7),2+IF(AND('Raw data'!I7='Real results'!C7,'Raw data'!J7='Real results'!D7),2,0),0),0),0) -> 2 | K8: =IFERROR(IF(AND(ISNUMBER('Real results'!C7),ISNUMBER('Real results'!D7),ISNUMBER('Raw data'!K7),ISNUMBER('Raw data'!L7)),IF(SIGN('Raw data'!K7-'Raw data'!L7)=SIGN('Real results'!C7-'Real results'!D7),2+IF(AND('Raw data'!K7='Real results'!C7,'Raw data'!L7='Real results'!D7),2,0),0),0),0) -> 2 | M8: =IFERROR(IF(AND(ISNUMBER('Real results'!C7),ISNUMBER('Real results'!D7),ISNUMBER('Raw data'!M7),ISNUMBER('Raw data'!N7)),IF(SIGN('Raw data'!M7-'Raw data'!N7)=SIGN('Real results'!C7-'Real results'!D7),2+IF(AND('Raw data'!M7='Real results'!C7,'Raw data'!N7='Real results'!D7),2,0),0),0),0) -> 0 | O8: =IFERROR(IF(AND(ISNUMBER('Real results'!C7),ISNUMBER('Real results'!D7),ISNUMBER('Raw data'!O7),ISNUMBER('Raw data'!P7)),IF(SIGN('Raw data'!O7-'Raw data'!P7)=SIGN('Real results'!C7-'Real results'!D7),2+IF(AND('Raw data'!O7='Real results'!C7,'Raw data'!P7='Real results'!D7),2,0),0),0),0) -> 0 | Q8: =IFERROR(IF(AND(ISNUMBER('Real results'!C7),ISNUMBER('Real results'!D7),ISNUMBER('Raw data'!Q7),ISNUMBER('Raw data'!R7)),IF(SIGN('Raw data'!Q7-'Raw data'!R7)=SIGN('Real results'!C7-'Real results'!D7),2+IF(AND('Raw data'!Q7='Real results'!C7,'Raw data'!R7='Real results'!D7),2,0),0),0),0) -> 0 | S8: =IFERROR(IF(AND(ISNUMBER('Real results'!C7),ISNUMBER('Real results'!D7),ISNUMBER('Raw data'!S7),ISNUMBER('Raw data'!T7)),IF(SIGN('Raw data'!S7-'Raw data'!T7)=SIGN('Real results'!C7-'Real results'!D7),2+IF(AND('Raw data'!S7='Real results'!C7,'Raw data'!T7='Real results'!D7),2,0),0),0),0) -> 0 | U8: =IFERROR(IF(AND(ISNUMBER('Real results'!C7),ISNUMBER('Real results'!D7),ISNUMBER('Raw data'!U7),ISNUMBER('Raw data'!V7)),IF(SIGN('Raw data'!U7-'Raw data'!V7)=SIGN('Real results'!C7-'Real results'!D7),2+IF(AND('Raw data'!U7='Real results'!C7,'Raw data'!V7='Real results'!D7),2,0),0),0),0) -> 0 | W8: =IFERROR(IF(AND(ISNUMBER('Real results'!C7),ISNUMBER('Real results'!D7),ISNUMBER('Raw data'!W7),ISNUMBER('Raw data'!X7)),IF(SIGN('Raw data'!W7-'Raw data'!X7)=SIGN('Real results'!C7-'Real results'!D7),2+IF(AND('Raw data'!W7='Real results'!C7,'Raw data'!X7='Real results'!D7),2,0),0),0),0) -> 0 | Y8: =IFERROR(IF(AND(ISNUMBER('Real results'!C7),ISNUMBER('Real results'!D7),ISNUMBER('Raw data'!Y7),ISNUMBER('Raw data'!Z7)),IF(SIGN('Raw data'!Y7-'Raw data'!Z7)=SIGN('Real results'!C7-'Real results'!D7),2+IF(AND('Raw data'!Y7='Real results'!C7,'Raw data'!Z7='Real results'!D7),2,0),0),0),0) -> 0 | AA8: =IFERROR(IF(AND(ISNUMBER('Real results'!C7),ISNUMBER('Real results'!D7),ISNUMBER('Raw data'!AA7),ISNUMBER('Raw data'!AB7)),IF(SIGN('Raw data'!AA7-'Raw data'!AB7)=SIGN('Real results'!C7-'Real results'!D7),2+IF(AND('Raw data'!AA7='Real results'!C7,'Raw data'!AB7='Real results'!D7),2,0),0),0),0) -> 0 | AC8: =IFERROR(IF(AND(ISNUMBER('Real results'!C7),ISNUMBER('Real results'!D7),ISNUMBER('Raw data'!AC7),ISNUMBER('Raw data'!AD7)),IF(SIGN('Raw data'!AC7-'Raw data'!AD7)=SIGN('Real results'!C7-'Real results'!D7),2+IF(AND('Raw data'!AC7='Real results'!C7,'Raw data'!AD7='Real results'!D7),2,0),0),0),0) -> 0 | AE8: =IFERROR(IF(AND(ISNUMBER('Real results'!C7),ISNUMBER('Real results'!D7),ISNUMBER('Raw data'!AE7),ISNUMBER('Raw data'!AF7)),IF(SIGN('Raw data'!AE7-'Raw data'!AF7)=SIGN('Real results'!C7-'Real results'!D7),2+IF(AND('Raw data'!AE7='Real results'!C7,'Raw data'!AF7='Real results'!D7),2,0),0),0),0) -> 0 | AG8: =IFERROR(IF(AND(ISNUMBER('Real results'!C7),ISNUMBER('Real results'!D7),ISNUMBER('Raw data'!AG7),ISNUMBER('Raw data'!AH7)),IF(SIGN('Raw data'!AG7-'Raw data'!AH7)=SIGN('Real results'!C7-'Real results'!D7),2+IF(AND('Raw data'!AG7='Real results'!C7,'Raw data'!AH7='Real results'!D7),2,0),0),0),0) -> 0 | AI8: =IFERROR(IF(AND(ISNUMBER('Real results'!C7),ISNUMBER('Real results'!D7),ISNUMBER('Raw data'!AI7),ISNUMBER('Raw data'!AJ7)),IF(SIGN('Raw data'!AI7-'Raw data'!AJ7)=SIGN('Real results'!C7-'Real results'!D7),2+IF(AND('Raw data'!AI7='Real results'!C7,'Raw data'!AJ7='Real results'!D7),2,0),0),0),0) -> 0 | AK8: =IFERROR(IF(AND(ISNUMBER('Real results'!C7),ISNUMBER('Real results'!D7),ISNUMBER('Raw data'!AK7),ISNUMBER('Raw data'!AL7)),IF(SIGN('Raw data'!AK7-'Raw data'!AL7)=SIGN('Real results'!C7-'Real results'!D7),2+IF(AND('Raw data'!AK7='Real results'!C7,'Raw data'!AL7='Real results'!D7),2,0),0),0),0) -> 0 | AM8: =IFERROR(IF(AND(ISNUMBER('Real results'!C7),ISNUMBER('Real results'!D7),ISNUMBER('Raw data'!AM7),ISNUMBER('Raw data'!AN7)),IF(SIGN('Raw data'!AM7-'Raw data'!AN7)=SIGN('Real results'!C7-'Real results'!D7),2+IF(AND('Raw data'!AM7='Real results'!C7,'Raw data'!AN7='Real results'!D7),2,0),0),0),0) -> 0 | AO8: =IFERROR(IF(AND(ISNUMBER('Real results'!C7),ISNUMBER('Real results'!D7),ISNUMBER('Raw data'!AO7),ISNUMBER('Raw data'!AP7)),IF(SIGN('Raw data'!AO7-'Raw data'!AP7)=SIGN('Real results'!C7-'Real results'!D7),2+IF(AND('Raw data'!AO7='Real results'!C7,'Raw data'!AP7='Real results'!D7),2,0),0),0),0) -> 0 | AQ8: =IFERROR(IF(AND(ISNUMBER('Real results'!C7),ISNUMBER('Real results'!D7),ISNUMBER('Raw data'!AQ7),ISNUMBER('Raw data'!AR7)),IF(SIGN('Raw data'!AQ7-'Raw data'!AR7)=SIGN('Real results'!C7-'Real results'!D7),2+IF(AND('Raw data'!AQ7='Real results'!C7,'Raw data'!AR7='Real results'!D7),2,0),0),0),0) -> 0 | AS8: =IFERROR(IF(AND(ISNUMBER('Real results'!C7),ISNUMBER('Real results'!D7),ISNUMBER('Raw data'!AS7),ISNUMBER('Raw data'!AT7)),IF(SIGN('Raw data'!AS7-'Raw data'!AT7)=SIGN('Real results'!C7-'Real results'!D7),2+IF(AND('Raw data'!AS7='Real results'!C7,'Raw data'!AT7='Real results'!D7),2,0),0),0),0) -> 0 | AU8: =IFERROR(IF(AND(ISNUMBER('Real results'!C7),ISNUMBER('Real results'!D7),ISNUMBER('Raw data'!AU7),ISNUMBER('Raw data'!AV7)),IF(SIGN('Raw data'!AU7-'Raw data'!AV7)=SIGN('Real results'!C7-'Real results'!D7),2+IF(AND('Raw data'!AU7='Real results'!C7,'Raw data'!AV7='Real results'!D7),2,0),0),0),0) -> 0 | AW8: =IFERROR(IF(AND(ISNUMBER('Real results'!C7),ISNUMBER('Real results'!D7),ISNUMBER('Raw data'!AW7),ISNUMBER('Raw data'!AX7)),IF(SIGN('Raw data'!AW7-'Raw data'!AX7)=SIGN('Real results'!C7-'Real results'!D7),2+IF(AND('Raw data'!AW7='Real results'!C7,'Raw data'!AX7='Real results'!D7),2,0),0),0),0) -> 0 | AY8: =IFERROR(IF(AND(ISNUMBER('Real results'!C7),ISNUMBER('Real results'!D7),ISNUMBER('Raw data'!AY7),ISNUMBER('Raw data'!AZ7)),IF(SIGN('Raw data'!AY7-'Raw data'!AZ7)=SIGN('Real results'!C7-'Real results'!D7),2+IF(AND('Raw data'!AY7='Real results'!C7,'Raw data'!AZ7='Real results'!D7),2,0),0),0),0) -> 0 | BA8: =IFERROR(IF(AND(ISNUMBER('Real results'!C7),ISNUMBER('Real results'!D7),ISNUMBER('Raw data'!BA7),ISNUMBER('Raw data'!BB7)),IF(SIGN('Raw data'!BA7-'Raw data'!BB7)=SIGN('Real results'!C7-'Real results'!D7),2+IF(AND('Raw data'!BA7='Real results'!C7,'Raw data'!BB7='Real results'!D7),2,0),0),0),0) -> 0 | BC8: =IFERROR(IF(AND(ISNUMBER('Real results'!C7),ISNUMBER('Real results'!D7),ISNUMBER('Raw data'!BC7),ISNUMBER('Raw data'!BD7)),IF(SIGN('Raw data'!BC7-'Raw data'!BD7)=SIGN('Real results'!C7-'Real results'!D7),2+IF(AND('Raw data'!BC7='Real results'!C7,'Raw data'!BD7='Real results'!D7),2,0),0),0),0) -> 0 | BE8: =IFERROR(IF(AND(ISNUMBER('Real results'!C7),ISNUMBER('Real results'!D7),ISNUMBER('Raw data'!BE7),ISNUMBER('Raw data'!BF7)),IF(SIGN('Raw data'!BE7-'Raw data'!BF7)=SIGN('Real results'!C7-'Real results'!D7),2+IF(AND('Raw data'!BE7='Real results'!C7,'Raw data'!BF7='Real results'!D7),2,0),0),0),0) -> 0 | BG8: =IFERROR(IF(AND(ISNUMBER('Real results'!C7),ISNUMBER('Real results'!D7),ISNUMBER('Raw data'!BG7),ISNUMBER('Raw data'!BH7)),IF(SIGN('Raw data'!BG7-'Raw data'!BH7)=SIGN('Real results'!C7-'Real results'!D7),2+IF(AND('Raw data'!BG7='Real results'!C7,'Raw data'!BH7='Real results'!D7),2,0),0),0),0) -> 0 | BI8: =IFERROR(IF(AND(ISNUMBER('Real results'!C7),ISNUMBER('Real results'!D7),ISNUMBER('Raw data'!BI7),ISNUMBER('Raw data'!BJ7)),IF(SIGN('Raw data'!BI7-'Raw data'!BJ7)=SIGN('Real results'!C7-'Real results'!D7),2+IF(AND('Raw data'!BI7='Real results'!C7,'Raw data'!BJ7='Real results'!D7),2,0),0),0),0) -> 0
B9: GA-M2: South Korea vs Czech Rep. | C9: =IFERROR(IF(AND(ISNUMBER('Real results'!C8),ISNUMBER('Real results'!D8),ISNUMBER(#REF!),ISNUMBER(#REF!)),IF(SIGN(#REF!-#REF!)=SIGN('Real results'!C8-'Real results'!D8),2+IF(AND(#REF!='Real results'!C8,#REF!='Real results'!D8),2,0),0),0),0) -> 0 | E9: =IFERROR(IF(AND(ISNUMBER('Real results'!C8),ISNUMBER('Real results'!D8),ISNUMBER('Raw data'!E7),ISNUMBER('Raw data'!F7)),IF(SIGN('Raw data'!E7-'Raw data'!F7)=SIGN('Real results'!C8-'Real results'!D8),2+IF(AND('Raw data'!E7='Real results'!C8,'Raw data'!F7='Real results'!D8),2,0),0),0),0) -> 2 | G9: =IFERROR(IF(AND(ISNUMBER('Real results'!C8),ISNUMBER('Real results'!D8),ISNUMBER('Raw data'!G8),ISNUMBER('Raw data'!H8)),IF(SIGN('Raw data'!G8-'Raw data'!H8)=SIGN('Real results'!C8-'Real results'!D8),2+IF(AND('Raw data'!G8='Real results'!C8,'Raw data'!H8='Real results'!D8),2,0),0),0),0) -> 0 | I9: =IFERROR(IF(AND(ISNUMBER('Real results'!C8),ISNUMBER('Real results'!D8),ISNUMBER('Raw data'!I8),ISNUMBER('Raw data'!J8)),IF(SIGN('Raw data'!I8-'Raw data'!J8)=SIGN('Real results'!C8-'Real results'!D8),2+IF(AND('Raw data'!I8='Real results'!C8,'Raw data'!J8='Real results'!D8),2,0),0),0),0) -> 4 | K9: =IFERROR(IF(AND(ISNUMBER('Real results'!C8),ISNUMBER('Real results'!D8),ISNUMBER('Raw data'!K8),ISNUMBER('Raw data'!L8)),IF(SIGN('Raw data'!K8-'Raw data'!L8)=SIGN('Real results'!C8-'Real results'!D8),2+IF(AND('Raw data'!K8='Real results'!C8,'Raw data'!L8='Real results'!D8),2,0),0),0),0) -> 4 | M9: =IFERROR(IF(AND(ISNUMBER('Real results'!C8),ISNUMBER('Real results'!D8),ISNUMBER('Raw data'!M8),ISNUMBER('Raw data'!N8)),IF(SIGN('Raw data'!M8-'Raw data'!N8)=SIGN('Real results'!C8-'Real results'!D8),2+IF(AND('Raw data'!M8='Real results'!C8,'Raw data'!N8='Real results'!D8),2,0),0),0),0) -> 0 | O9: =IFERROR(IF(AND(ISNUMBER('Real results'!C8),ISNUMBER('Real results'!D8),ISNUMBER('Raw data'!O8),ISNUMBER('Raw data'!P8)),IF(SIGN('Raw data'!O8-'Raw data'!P8)=SIGN('Real results'!C8-'Real results'!D8),2+IF(AND('Raw data'!O8='Real results'!C8,'Raw data'!P8='Real results'!D8),2,0),0),0),0) -> 0 | Q9: =IFERROR(IF(AND(ISNUMBER('Real results'!C8),ISNUMBER('Real results'!D8),ISNUMBER('Raw data'!Q8),ISNUMBER('Raw data'!R8)),IF(SIGN('Raw data'!Q8-'Raw data'!R8)=SIGN('Real results'!C8-'Real results'!D8),2+IF(AND('Raw data'!Q8='Real results'!C8,'Raw data'!R8='Real results'!D8),2,0),0),0),0) -> 0 | S9: =IFERROR(IF(AND(ISNUMBER('Real results'!C8),ISNUMBER('Real results'!D8),ISNUMBER('Raw data'!S8),ISNUMBER('Raw data'!T8)),IF(SIGN('Raw data'!S8-'Raw data'!T8)=SIGN('Real results'!C8-'Real results'!D8),2+IF(AND('Raw data'!S8='Real results'!C8,'Raw data'!T8='Real results'!D8),2,0),0),0),0) -> 0 | U9: =IFERROR(IF(AND(ISNUMBER('Real results'!C8),ISNUMBER('Real results'!D8),ISNUMBER('Raw data'!U8),ISNUMBER('Raw data'!V8)),IF(SIGN('Raw data'!U8-'Raw data'!V8)=SIGN('Real results'!C8-'Real results'!D8),2+IF(AND('Raw data'!U8='Real results'!C8,'Raw data'!V8='Real results'!D8),2,0),0),0),0) -> 0 | W9: =IFERROR(IF(AND(ISNUMBER('Real results'!C8),ISNUMBER('Real results'!D8),ISNUMBER('Raw data'!W8),ISNUMBER('Raw data'!X8)),IF(SIGN('Raw data'!W8-'Raw data'!X8)=SIGN('Real results'!C8-'Real results'!D8),2+IF(AND('Raw data'!W8='Real results'!C8,'Raw data'!X8='Real results'!D8),2,0),0),0),0) -> 0 | Y9: =IFERROR(IF(AND(ISNUMBER('Real results'!C8),ISNUMBER('Real results'!D8),ISNUMBER('Raw data'!Y8),ISNUMBER('Raw data'!Z8)),IF(SIGN('Raw data'!Y8-'Raw data'!Z8)=SIGN('Real results'!C8-'Real results'!D8),2+IF(AND('Raw data'!Y8='Real results'!C8,'Raw data'!Z8='Real results'!D8),2,0),0),0),0) -> 0 | AA9: =IFERROR(IF(AND(ISNUMBER('Real results'!C8),ISNUMBER('Real results'!D8),ISNUMBER('Raw data'!AA8),ISNUMBER('Raw data'!AB8)),IF(SIGN('Raw data'!AA8-'Raw data'!AB8)=SIGN('Real results'!C8-'Real results'!D8),2+IF(AND('Raw data'!AA8='Real results'!C8,'Raw data'!AB8='Real results'!D8),2,0),0),0),0) -> 0 | AC9: =IFERROR(IF(AND(ISNUMBER('Real results'!C8),ISNUMBER('Real results'!D8),ISNUMBER('Raw data'!AC8),ISNUMBER('Raw data'!AD8)),IF(SIGN('Raw data'!AC8-'Raw data'!AD8)=SIGN('Real results'!C8-'Real results'!D8),2+IF(AND('Raw data'!AC8='Real results'!C8,'Raw data'!AD8='Real results'!D8),2,0),0),0),0) -> 0 | AE9: =IFERROR(IF(AND(ISNUMBER('Real results'!C8),ISNUMBER('Real results'!D8),ISNUMBER('Raw data'!AE8),ISNUMBER('Raw data'!AF8)),IF(SIGN('Raw data'!AE8-'Raw data'!AF8)=SIGN('Real results'!C8-'Real results'!D8),2+IF(AND('Raw data'!AE8='Real results'!C8,'Raw data'!AF8='Real results'!D8),2,0),0),0),0) -> 0 | AG9: =IFERROR(IF(AND(ISNUMBER('Real results'!C8),ISNUMBER('Real results'!D8),ISNUMBER('Raw data'!AG8),ISNUMBER('Raw data'!AH8)),IF(SIGN('Raw data'!AG8-'Raw data'!AH8)=SIGN('Real results'!C8-'Real results'!D8),2+IF(AND('Raw data'!AG8='Real results'!C8,'Raw data'!AH8='Real results'!D8),2,0),0),0),0) -> 0 | AI9: =IFERROR(IF(AND(ISNUMBER('Real results'!C8),ISNUMBER('Real results'!D8),ISNUMBER('Raw data'!AI8),ISNUMBER('Raw data'!AJ8)),IF(SIGN('Raw data'!AI8-'Raw data'!AJ8)=SIGN('Real results'!C8-'Real results'!D8),2+IF(AND('Raw data'!AI8='Real results'!C8,'Raw data'!AJ8='Real results'!D8),2,0),0),0),0) -> 0 | AK9: =IFERROR(IF(AND(ISNUMBER('Real results'!C8),ISNUMBER('Real results'!D8),ISNUMBER('Raw data'!AK8),ISNUMBER('Raw data'!AL8)),IF(SIGN('Raw data'!AK8-'Raw data'!AL8)=SIGN('Real results'!C8-'Real results'!D8),2+IF(AND('Raw data'!AK8='Real results'!C8,'Raw data'!AL8='Real results'!D8),2,0),0),0),0) -> 0 | AM9: =IFERROR(IF(AND(ISNUMBER('Real results'!C8),ISNUMBER('Real results'!D8),ISNUMBER('Raw data'!AM8),ISNUMBER('Raw data'!AN8)),IF(SIGN('Raw data'!AM8-'Raw data'!AN8)=SIGN('Real results'!C8-'Real results'!D8),2+IF(AND('Raw data'!AM8='Real results'!C8,'Raw data'!AN8='Real results'!D8),2,0),0),0),0) -> 0 | AO9: =IFERROR(IF(AND(ISNUMBER('Real results'!C8),ISNUMBER('Real results'!D8),ISNUMBER('Raw data'!AO8),ISNUMBER('Raw data'!AP8)),IF(SIGN('Raw data'!AO8-'Raw data'!AP8)=SIGN('Real results'!C8-'Real results'!D8),2+IF(AND('Raw data'!AO8='Real results'!C8,'Raw data'!AP8='Real results'!D8),2,0),0),0),0) -> 0 | AQ9: =IFERROR(IF(AND(ISNUMBER('Real results'!C8),ISNUMBER('Real results'!D8),ISNUMBER('Raw data'!AQ8),ISNUMBER('Raw data'!AR8)),IF(SIGN('Raw data'!AQ8-'Raw data'!AR8)=SIGN('Real results'!C8-'Real results'!D8),2+IF(AND('Raw data'!AQ8='Real results'!C8,'Raw data'!AR8='Real results'!D8),2,0),0),0),0) -> 0 | AS9: =IFERROR(IF(AND(ISNUMBER('Real results'!C8),ISNUMBER('Real results'!D8),ISNUMBER('Raw data'!AS8),ISNUMBER('Raw data'!AT8)),IF(SIGN('Raw data'!AS8-'Raw data'!AT8)=SIGN('Real results'!C8-'Real results'!D8),2+IF(AND('Raw data'!AS8='Real results'!C8,'Raw data'!AT8='Real results'!D8),2,0),0),0),0) -> 0 | AU9: =IFERROR(IF(AND(ISNUMBER('Real results'!C8),ISNUMBER('Real results'!D8),ISNUMBER('Raw data'!AU8),ISNUMBER('Raw data'!AV8)),IF(SIGN('Raw data'!AU8-'Raw data'!AV8)=SIGN('Real results'!C8-'Real results'!D8),2+IF(AND('Raw data'!AU8='Real results'!C8,'Raw data'!AV8='Real results'!D8),2,0),0),0),0) -> 0 | AW9: =IFERROR(IF(AND(ISNUMBER('Real results'!C8),ISNUMBER('Real results'!D8),ISNUMBER('Raw data'!AW8),ISNUMBER('Raw data'!AX8)),IF(SIGN('Raw data'!AW8-'Raw data'!AX8)=SIGN('Real results'!C8-'Real results'!D8),2+IF(AND('Raw data'!AW8='Real results'!C8,'Raw data'!AX8='Real results'!D8),2,0),0),0),0) -> 0 | AY9: =IFERROR(IF(AND(ISNUMBER('Real results'!C8),ISNUMBER('Real results'!D8),ISNUMBER('Raw data'!AY8),ISNUMBER('Raw data'!AZ8)),IF(SIGN('Raw data'!AY8-'Raw data'!AZ8)=SIGN('Real results'!C8-'Real results'!D8),2+IF(AND('Raw data'!AY8='Real results'!C8,'Raw data'!AZ8='Real results'!D8),2,0),0),0),0) -> 0 | BA9: =IFERROR(IF(AND(ISNUMBER('Real results'!C8),ISNUMBER('Real results'!D8),ISNUMBER('Raw data'!BA8),ISNUMBER('Raw data'!BB8)),IF(SIGN('Raw data'!BA8-'Raw data'!BB8)=SIGN('Real results'!C8-'Real results'!D8),2+IF(AND('Raw data'!BA8='Real results'!C8,'Raw data'!BB8='Real results'!D8),2,0),0),0),0) -> 0 | BC9: =IFERROR(IF(AND(ISNUMBER('Real results'!C8),ISNUMBER('Real results'!D8),ISNUMBER('Raw data'!BC8),ISNUMBER('Raw data'!BD8)),IF(SIGN('Raw data'!BC8-'Raw data'!BD8)=SIGN('Real results'!C8-'Real results'!D8),2+IF(AND('Raw data'!BC8='Real results'!C8,'Raw data'!BD8='Real results'!D8),2,0),0),0),0) -> 0 | BE9: =IFERROR(IF(AND(ISNUMBER('Real results'!C8),ISNUMBER('Real results'!D8),ISNUMBER('Raw data'!BE8),ISNUMBER('Raw data'!BF8)),IF(SIGN('Raw data'!BE8-'Raw data'!BF8)=SIGN('Real results'!C8-'Real results'!D8),2+IF(AND('Raw data'!BE8='Real results'!C8,'Raw data'!BF8='Real results'!D8),2,0),0),0),0) -> 0 | BG9: =IFERROR(IF(AND(ISNUMBER('Real results'!C8),ISNUMBER('Real results'!D8),ISNUMBER('Raw data'!BG8),ISNUMBER('Raw data'!BH8)),IF(SIGN('Raw data'!BG8-'Raw data'!BH8)=SIGN('Real results'!C8-'Real results'!D8),2+IF(AND('Raw data'!BG8='Real results'!C8,'Raw data'!BH8='Real results'!D8),2,0),0),0),0) -> 0 | BI9: =IFERROR(IF(AND(ISNUMBER('Real results'!C8),ISNUMBER('Real results'!D8),ISNUMBER('Raw data'!BI8),ISNUMBER('Raw data'!BJ8)),IF(SIGN('Raw data'!BI8-'Raw data'!BJ8)=SIGN('Real results'!C8-'Real results'!D8),2+IF(AND('Raw data'!BI8='Real results'!C8,'Raw data'!BJ8='Real results'!D8),2,0),0),0),0) -> 0
B10: GA-M3: Czech Rep. vs South Africa | C10: =IFERROR(IF(AND(ISNUMBER('Real results'!C9),ISNUMBER('Real results'!D9),ISNUMBER('Raw data'!C7),ISNUMBER('Raw data'!D7)),IF(SIGN('Raw data'!C7-'Raw data'!D7)=SIGN('Real results'!C9-'Real results'!D9),2+IF(AND('Raw data'!C7='Real results'!C9,'Raw data'!D7='Real results'!D9),2,0),0),0),0) -> 0 | E10: =IFERROR(IF(AND(ISNUMBER('Real results'!C9),ISNUMBER('Real results'!D9),ISNUMBER('Raw data'!E8),ISNUMBER('Raw data'!F8)),IF(SIGN('Raw data'!E8-'Raw data'!F8)=SIGN('Real results'!C9-'Real results'!D9),2+IF(AND('Raw data'!E8='Real results'!C9,'Raw data'!F8='Real results'!D9),2,0),0),0),0) -> 4 | G10: =IFERROR(IF(AND(ISNUMBER('Real results'!C9),ISNUMBER('Real results'!D9),ISNUMBER('Raw data'!G9),ISNUMBER('Raw data'!H9)),IF(SIGN('Raw data'!G9-'Raw data'!H9)=SIGN('Real results'!C9-'Real results'!D9),2+IF(AND('Raw data'!G9='Real results'!C9,'Raw data'!H9='Real results'!D9),2,0),0),0),0) -> 0 | I10: =IFERROR(IF(AND(ISNUMBER('Real results'!C9),ISNUMBER('Real results'!D9),ISNUMBER('Raw data'!I9),ISNUMBER('Raw data'!J9)),IF(SIGN('Raw data'!I9-'Raw data'!J9)=SIGN('Real results'!C9-'Real results'!D9),2+IF(AND('Raw data'!I9='Real results'!C9,'Raw data'!J9='Real results'!D9),2,0),0),0),0) -> 0 | K10: =IFERROR(IF(AND(ISNUMBER('Real results'!C9),ISNUMBER('Real results'!D9),ISNUMBER('Raw data'!K9),ISNUMBER('Raw data'!L9)),IF(SIGN('Raw data'!K9-'Raw data'!L9)=SIGN('Real results'!C9-'Real results'!D9),2+IF(AND('Raw data'!K9='Real results'!C9,'Raw data'!L9='Real results'!D9),2,0),0),0),0) -> 0 | M10: =IFERROR(IF(AND(ISNUMBER('Real results'!C9),ISNUMBER('Real results'!D9),ISNUMBER('Raw data'!M9),ISNUMBER('Raw data'!N9)),IF(SIGN('Raw data'!M9-'Raw data'!N9)=SIGN('Real results'!C9-'Real results'!D9),2+IF(AND('Raw data'!M9='Real results'!C9,'Raw data'!N9='Real results'!D9),2,0),0),0),0) -> 0 | O10: =IFERROR(IF(AND(ISNUMBER('Real results'!C9),ISNUMBER('Real results'!D9),ISNUMBER('Raw data'!O9),ISNUMBER('Raw data'!P9)),IF(SIGN('Raw data'!O9-'Raw data'!P9)=SIGN('Real results'!C9-'Real results'!D9),2+IF(AND('Raw data'!O9='Real results'!C9,'Raw data'!P9='Real results'!D9),2,0),0),0),0) -> 0 | Q10: =IFERROR(IF(AND(ISNUMBER('Real results'!C9),ISNUMBER('Real results'!D9),ISNUMBER('Raw data'!Q9),ISNUMBER('Raw data'!R9)),IF(SIGN('Raw data'!Q9-'Raw data'!R9)=SIGN('Real results'!C9-'Real results'!D9),2+IF(AND('Raw data'!Q9='Real results'!C9,'Raw data'!R9='Real results'!D9),2,0),0),0),0) -> 0 | S10: =IFERROR(IF(AND(ISNUMBER('Real results'!C9),ISNUMBER('Real results'!D9),ISNUMBER('Raw data'!S9),ISNUMBER('Raw data'!T9)),IF(SIGN('Raw data'!S9-'Raw data'!T9)=SIGN('Real results'!C9-'Real results'!D9),2+IF(AND('Raw data'!S9='Real results'!C9,'Raw data'!T9='Real results'!D9),2,0),0),0),0) -> 0 | U10: =IFERROR(IF(AND(ISNUMBER('Real results'!C9),ISNUMBER('Real results'!D9),ISNUMBER('Raw data'!U9),ISNUMBER('Raw data'!V9)),IF(SIGN('Raw data'!U9-'Raw data'!V9)=SIGN('Real results'!C9-'Real results'!D9),2+IF(AND('Raw data'!U9='Real results'!C9,'Raw data'!V9='Real results'!D9),2,0),0),0),0) -> 0 | W10: =IFERROR(IF(AND(ISNUMBER('Real results'!C9),ISNUMBER('Real results'!D9),ISNUMBER('Raw data'!W9),ISNUMBER('Raw data'!X9)),IF(SIGN('Raw data'!W9-'Raw data'!X9)=SIGN('Real results'!C9-'Real results'!D9),2+IF(AND('Raw data'!W9='Real results'!C9,'Raw data'!X9='Real results'!D9),2,0),0),0),0) -> 0 | Y10: =IFERROR(IF(AND(ISNUMBER('Real results'!C9),ISNUMBER('Real results'!D9),ISNUMBER('Raw data'!Y9),ISNUMBER('Raw data'!Z9)),IF(SIGN('Raw data'!Y9-'Raw data'!Z9)=SIGN('Real results'!C9-'Real results'!D9),2+IF(AND('Raw data'!Y9='Real results'!C9,'Raw data'!Z9='Real results'!D9),2,0),0),0),0) -> 0 | AA10: =IFERROR(IF(AND(ISNUMBER('Real results'!C9),ISNUMBER('Real results'!D9),ISNUMBER('Raw data'!AA9),ISNUMBER('Raw data'!AB9)),IF(SIGN('Raw data'!AA9-'Raw data'!AB9)=SIGN('Real results'!C9-'Real results'!D9),2+IF(AND('Raw data'!AA9='Real results'!C9,'Raw data'!AB9='Real results'!D9),2,0),0),0),0) -> 0 | AC10: =IFERROR(IF(AND(ISNUMBER('Real results'!C9),ISNUMBER('Real results'!D9),ISNUMBER('Raw data'!AC9),ISNUMBER('Raw data'!AD9)),IF(SIGN('Raw data'!AC9-'Raw data'!AD9)=SIGN('Real results'!C9-'Real results'!D9),2+IF(AND('Raw data'!AC9='Real results'!C9,'Raw data'!AD9='Real results'!D9),2,0),0),0),0) -> 0 | AE10: =IFERROR(IF(AND(ISNUMBER('Real results'!C9),ISNUMBER('Real results'!D9),ISNUMBER('Raw data'!AE9),ISNUMBER('Raw data'!AF9)),IF(SIGN('Raw data'!AE9-'Raw data'!AF9)=SIGN('Real results'!C9-'Real results'!D9),2+IF(AND('Raw data'!AE9='Real results'!C9,'Raw data'!AF9='Real results'!D9),2,0),0),0),0) -> 0 | AG10: =IFERROR(IF(AND(ISNUMBER('Real results'!C9),ISNUMBER('Real results'!D9),ISNUMBER('Raw data'!AG9),ISNUMBER('Raw data'!AH9)),IF(SIGN('Raw data'!AG9-'Raw data'!AH9)=SIGN('Real results'!C9-'Real results'!D9),2+IF(AND('Raw data'!AG9='Real results'!C9,'Raw data'!AH9='Real results'!D9),2,0),0),0),0) -> 0 | AI10: =IFERROR(IF(AND(ISNUMBER('Real results'!C9),ISNUMBER('Real results'!D9),ISNUMBER('Raw data'!AI9),ISNUMBER('Raw data'!AJ9)),IF(SIGN('Raw data'!AI9-'Raw data'!AJ9)=SIGN('Real results'!C9-'Real results'!D9),2+IF(AND('Raw data'!AI9='Real results'!C9,'Raw data'!AJ9='Real results'!D9),2,0),0),0),0) -> 0 | AK10: =IFERROR(IF(AND(ISNUMBER('Real results'!C9),ISNUMBER('Real results'!D9),ISNUMBER('Raw data'!AK9),ISNUMBER('Raw data'!AL9)),IF(SIGN('Raw data'!AK9-'Raw data'!AL9)=SIGN('Real results'!C9-'Real results'!D9),2+IF(AND('Raw data'!AK9='Real results'!C9,'Raw data'!AL9='Real results'!D9),2,0),0),0),0) -> 0 | AM10: =IFERROR(IF(AND(ISNUMBER('Real results'!C9),ISNUMBER('Real results'!D9),ISNUMBER('Raw data'!AM9),ISNUMBER('Raw data'!AN9)),IF(SIGN('Raw data'!AM9-'Raw data'!AN9)=SIGN('Real results'!C9-'Real results'!D9),2+IF(AND('Raw data'!AM9='Real results'!C9,'Raw data'!AN9='Real results'!D9),2,0),0),0),0) -> 0 | AO10: =IFERROR(IF(AND(ISNUMBER('Real results'!C9),ISNUMBER('Real results'!D9),ISNUMBER('Raw data'!AO9),ISNUMBER('Raw data'!AP9)),IF(SIGN('Raw data'!AO9-'Raw data'!AP9)=SIGN('Real results'!C9-'Real results'!D9),2+IF(AND('Raw data'!AO9='Real results'!C9,'Raw data'!AP9='Real results'!D9),2,0),0),0),0) -> 0 | AQ10: =IFERROR(IF(AND(ISNUMBER('Real results'!C9),ISNUMBER('Real results'!D9),ISNUMBER('Raw data'!AQ9),ISNUMBER('Raw data'!AR9)),IF(SIGN('Raw data'!AQ9-'Raw data'!AR9)=SIGN('Real results'!C9-'Real results'!D9),2+IF(AND('Raw data'!AQ9='Real results'!C9,'Raw data'!AR9='Real results'!D9),2,0),0),0),0) -> 0 | AS10: =IFERROR(IF(AND(ISNUMBER('Real results'!C9),ISNUMBER('Real results'!D9),ISNUMBER('Raw data'!AS9),ISNUMBER('Raw data'!AT9)),IF(SIGN('Raw data'!AS9-'Raw data'!AT9)=SIGN('Real results'!C9-'Real results'!D9),2+IF(AND('Raw data'!AS9='Real results'!C9,'Raw data'!AT9='Real results'!D9),2,0),0),0),0) -> 0 | AU10: =IFERROR(IF(AND(ISNUMBER('Real results'!C9),ISNUMBER('Real results'!D9),ISNUMBER('Raw data'!AU9),ISNUMBER('Raw data'!AV9)),IF(SIGN('Raw data'!AU9-'Raw data'!AV9)=SIGN('Real results'!C9-'Real results'!D9),2+IF(AND('Raw data'!AU9='Real results'!C9,'Raw data'!AV9='Real results'!D9),2,0),0),0),0) -> 0 | AW10: =IFERROR(IF(AND(ISNUMBER('Real results'!C9),ISNUMBER('Real results'!D9),ISNUMBER('Raw data'!AW9),ISNUMBER('Raw data'!AX9)),IF(SIGN('Raw data'!AW9-'Raw data'!AX9)=SIGN('Real results'!C9-'Real results'!D9),2+IF(AND('Raw data'!AW9='Real results'!C9,'Raw data'!AX9='Real results'!D9),2,0),0),0),0) -> 0 | AY10: =IFERROR(IF(AND(ISNUMBER('Real results'!C9),ISNUMBER('Real results'!D9),ISNUMBER('Raw data'!AY9),ISNUMBER('Raw data'!AZ9)),IF(SIGN('Raw data'!AY9-'Raw data'!AZ9)=SIGN('Real results'!C9-'Real results'!D9),2+IF(AND('Raw data'!AY9='Real results'!C9,'Raw data'!AZ9='Real results'!D9),2,0),0),0),0) -> 0 | BA10: =IFERROR(IF(AND(ISNUMBER('Real results'!C9),ISNUMBER('Real results'!D9),ISNUMBER('Raw data'!BA9),ISNUMBER('Raw data'!BB9)),IF(SIGN('Raw data'!BA9-'Raw data'!BB9)=SIGN('Real results'!C9-'Real results'!D9),2+IF(AND('Raw data'!BA9='Real results'!C9,'Raw data'!BB9='Real results'!D9),2,0),0),0),0) -> 0 | BC10: =IFERROR(IF(AND(ISNUMBER('Real results'!C9),ISNUMBER('Real results'!D9),ISNUMBER('Raw data'!BC9),ISNUMBER('Raw data'!BD9)),IF(SIGN('Raw data'!BC9-'Raw data'!BD9)=SIGN('Real results'!C9-'Real results'!D9),2+IF(AND('Raw data'!BC9='Real results'!C9,'Raw data'!BD9='Real results'!D9),2,0),0),0),0) -> 0 | BE10: =IFERROR(IF(AND(ISNUMBER('Real results'!C9),ISNUMBER('Real results'!D9),ISNUMBER('Raw data'!BE9),ISNUMBER('Raw data'!BF9)),IF(SIGN('Raw data'!BE9-'Raw data'!BF9)=SIGN('Real results'!C9-'Real results'!D9),2+IF(AND('Raw data'!BE9='Real results'!C9,'Raw data'!BF9='Real results'!D9),2,0),0),0),0) -> 0 | BG10: =IFERROR(IF(AND(ISNUMBER('Real results'!C9),ISNUMBER('Real results'!D9),ISNUMBER('Raw data'!BG9),ISNUMBER('Raw data'!BH9)),IF(SIGN('Raw data'!BG9-'Raw data'!BH9)=SIGN('Real results'!C9-'Real results'!D9),2+IF(AND('Raw data'!BG9='Real results'!C9,'Raw data'!BH9='Real results'!D9),2,0),0),0),0) -> 0 | BI10: =IFERROR(IF(AND(ISNUMBER('Real results'!C9),ISNUMBER('Real results'!D9),ISNUMBER('Raw data'!BI9),ISNUMBER('Raw data'!BJ9)),IF(SIGN('Raw data'!BI9-'Raw data'!BJ9)=SIGN('Real results'!C9-'Real results'!D9),2+IF(AND('Raw data'!BI9='Real results'!C9,'Raw data'!BJ9='Real results'!D9),2,0),0),0),0) -> 0
B11: GA-M4: Mexico vs South Korea | C11: =IFERROR(IF(AND(ISNUMBER('Real results'!C10),ISNUMBER('Real results'!D10),ISNUMBER('Raw data'!C8),ISNUMBER('Raw data'!D8)),IF(SIGN('Raw data'!C8-'Raw data'!D8)=SIGN('Real results'!C10-'Real results'!D10),2+IF(AND('Raw data'!C8='Real results'!C10,'Raw data'!D8='Real results'!D10),2,0),0),0),0) -> 0 | E11: =IFERROR(IF(AND(ISNUMBER('Real results'!C10),ISNUMBER('Real results'!D10),ISNUMBER('Raw data'!E9),ISNUMBER('Raw data'!F9)),IF(SIGN('Raw data'!E9-'Raw data'!F9)=SIGN('Real results'!C10-'Real results'!D10),2+IF(AND('Raw data'!E9='Real results'!C10,'Raw data'!F9='Real results'!D10),2,0),0),0),0) -> 4 | G11: =IFERROR(IF(AND(ISNUMBER('Real results'!C10),ISNUMBER('Real results'!D10),ISNUMBER('Raw data'!G10),ISNUMBER('Raw data'!H10)),IF(SIGN('Raw data'!G10-'Raw data'!H10)=SIGN('Real results'!C10-'Real results'!D10),2+IF(AND('Raw data'!G10='Real results'!C10,'Raw data'!H10='Real results'!D10),2,0),0),0),0) -> 2 | I11: =IFERROR(IF(AND(ISNUMBER('Real results'!C10),ISNUMBER('Real results'!D10),ISNUMBER('Raw data'!I10),ISNUMBER('Raw data'!J10)),IF(SIGN('Raw data'!I10-'Raw data'!J10)=SIGN('Real results'!C10-'Real results'!D10),2+IF(AND('Raw data'!I10='Real results'!C10,'Raw data'!J10='Real results'!D10),2,0),0),0),0) -> 0 | K11: =IFERROR(IF(AND(ISNUMBER('Real results'!C10),ISNUMBER('Real results'!D10),ISNUMBER('Raw data'!K10),ISNUMBER('Raw data'!L10)),IF(SIGN('Raw data'!K10-'Raw data'!L10)=SIGN('Real results'!C10-'Real results'!D10),2+IF(AND('Raw data'!K10='Real results'!C10,'Raw data'!L10='Real results'!D10),2,0),0),0),0) -> 2 | M11: =IFERROR(IF(AND(ISNUMBER('Real results'!C10),ISNUMBER('Real results'!D10),ISNUMBER('Raw data'!M10),ISNUMBER('Raw data'!N10)),IF(SIGN('Raw data'!M10-'Raw data'!N10)=SIGN('Real results'!C10-'Real results'!D10),2+IF(AND('Raw data'!M10='Real results'!C10,'Raw data'!N10='Real results'!D10),2,0),0),0),0) -> 0 | O11: =IFERROR(IF(AND(ISNUMBER('Real results'!C10),ISNUMBER('Real results'!D10),ISNUMBER('Raw data'!O10),ISNUMBER('Raw data'!P10)),IF(SIGN('Raw data'!O10-'Raw data'!P10)=SIGN('Real results'!C10-'Real results'!D10),2+IF(AND('Raw data'!O10='Real results'!C10,'Raw data'!P10='Real results'!D10),2,0),0),0),0) -> 0 | Q11: =IFERROR(IF(AND(ISNUMBER('Real results'!C10),ISNUMBER('Real results'!D10),ISNUMBER('Raw data'!Q10),ISNUMBER('Raw data'!R10)),IF(SIGN('Raw data'!Q10-'Raw data'!R10)=SIGN('Real results'!C10-'Real results'!D10),2+IF(AND('Raw data'!Q10='Real results'!C10,'Raw data'!R10='Real results'!D10),2,0),0),0),0) -> 0 | S11: =IFERROR(IF(AND(ISNUMBER('Real results'!C10),ISNUMBER('Real results'!D10),ISNUMBER('Raw data'!S10),ISNUMBER('Raw data'!T10)),IF(SIGN('Raw data'!S10-'Raw data'!T10)=SIGN('Real results'!C10-'Real results'!D10),2+IF(AND('Raw data'!S10='Real results'!C10,'Raw data'!T10='Real results'!D10),2,0),0),0),0) -> 0 | U11: =IFERROR(IF(AND(ISNUMBER('Real results'!C10),ISNUMBER('Real results'!D10),ISNUMBER('Raw data'!U10),ISNUMBER('Raw data'!V10)),IF(SIGN('Raw data'!U10-'Raw data'!V10)=SIGN('Real results'!C10-'Real results'!D10),2+IF(AND('Raw data'!U10='Real results'!C10,'Raw data'!V10='Real results'!D10),2,0),0),0),0) -> 0 | W11: =IFERROR(IF(AND(ISNUMBER('Real results'!C10),ISNUMBER('Real results'!D10),ISNUMBER('Raw data'!W10),ISNUMBER('Raw data'!X10)),IF(SIGN('Raw data'!W10-'Raw data'!X10)=SIGN('Real results'!C10-'Real results'!D10),2+IF(AND('Raw data'!W10='Real results'!C10,'Raw data'!X10='Real results'!D10),2,0),0),0),0) -> 0 | Y11: =IFERROR(IF(AND(ISNUMBER('Real results'!C10),ISNUMBER('Real results'!D10),ISNUMBER('Raw data'!Y10),ISNUMBER('Raw data'!Z10)),IF(SIGN('Raw data'!Y10-'Raw data'!Z10)=SIGN('Real results'!C10-'Real results'!D10),2+IF(AND('Raw data'!Y10='Real results'!C10,'Raw data'!Z10='Real results'!D10),2,0),0),0),0) -> 0 | AA11: =IFERROR(IF(AND(ISNUMBER('Real results'!C10),ISNUMBER('Real results'!D10),ISNUMBER('Raw data'!AA10),ISNUMBER('Raw data'!AB10)),IF(SIGN('Raw data'!AA10-'Raw data'!AB10)=SIGN('Real results'!C10-'Real results'!D10),2+IF(AND('Raw data'!AA10='Real results'!C10,'Raw data'!AB10='Real results'!D10),2,0),0),0),0) -> 0 | AC11: =IFERROR(IF(AND(ISNUMBER('Real results'!C10),ISNUMBER('Real results'!D10),ISNUMBER('Raw data'!AC10),ISNUMBER('Raw data'!AD10)),IF(SIGN('Raw data'!AC10-'Raw data'!AD10)=SIGN('Real results'!C10-'Real results'!D10),2+IF(AND('Raw data'!AC10='Real results'!C10,'Raw data'!AD10='Real results'!D10),2,0),0),0),0) -> 0 | AE11: =IFERROR(IF(AND(ISNUMBER('Real results'!C10),ISNUMBER('Real results'!D10),ISNUMBER('Raw data'!AE10),ISNUMBER('Raw data'!AF10)),IF(SIGN('Raw data'!AE10-'Raw data'!AF10)=SIGN('Real results'!C10-'Real results'!D10),2+IF(AND('Raw data'!AE10='Real results'!C10,'Raw data'!AF10='Real results'!D10),2,0),0),0),0) -> 0 | AG11: =IFERROR(IF(AND(ISNUMBER('Real results'!C10),ISNUMBER('Real results'!D10),ISNUMBER('Raw data'!AG10),ISNUMBER('Raw data'!AH10)),IF(SIGN('Raw data'!AG10-'Raw data'!AH10)=SIGN('Real results'!C10-'Real results'!D10),2+IF(AND('Raw data'!AG10='Real results'!C10,'Raw data'!AH10='Real results'!D10),2,0),0),0),0) -> 0 | AI11: =IFERROR(IF(AND(ISNUMBER('Real results'!C10),ISNUMBER('Real results'!D10),ISNUMBER('Raw data'!AI10),ISNUMBER('Raw data'!AJ10)),IF(SIGN('Raw data'!AI10-'Raw data'!AJ10)=SIGN('Real results'!C10-'Real results'!D10),2+IF(AND('Raw data'!AI10='Real results'!C10,'Raw data'!AJ10='Real results'!D10),2,0),0),0),0) -> 0 | AK11: =IFERROR(IF(AND(ISNUMBER('Real results'!C10),ISNUMBER('Real results'!D10),ISNUMBER('Raw data'!AK10),ISNUMBER('Raw data'!AL10)),IF(SIGN('Raw data'!AK10-'Raw data'!AL10)=SIGN('Real results'!C10-'Real results'!D10),2+IF(AND('Raw data'!AK10='Real results'!C10,'Raw data'!AL10='Real results'!D10),2,0),0),0),0) -> 0 | AM11: =IFERROR(IF(AND(ISNUMBER('Real results'!C10),ISNUMBER('Real results'!D10),ISNUMBER('Raw data'!AM10),ISNUMBER('Raw data'!AN10)),IF(SIGN('Raw data'!AM10-'Raw data'!AN10)=SIGN('Real results'!C10-'Real results'!D10),2+IF(AND('Raw data'!AM10='Real results'!C10,'Raw data'!AN10='Real results'!D10),2,0),0),0),0) -> 0 | AO11: =IFERROR(IF(AND(ISNUMBER('Real results'!C10),ISNUMBER('Real results'!D10),ISNUMBER('Raw data'!AO10),ISNUMBER('Raw data'!AP10)),IF(SIGN('Raw data'!AO10-'Raw data'!AP10)=SIGN('Real results'!C10-'Real results'!D10),2+IF(AND('Raw data'!AO10='Real results'!C10,'Raw data'!AP10='Real results'!D10),2,0),0),0),0) -> 0 | AQ11: =IFERROR(IF(AND(ISNUMBER('Real results'!C10),ISNUMBER('Real results'!D10),ISNUMBER('Raw data'!AQ10),ISNUMBER('Raw data'!AR10)),IF(SIGN('Raw data'!AQ10-'Raw data'!AR10)=SIGN('Real results'!C10-'Real results'!D10),2+IF(AND('Raw data'!AQ10='Real results'!C10,'Raw data'!AR10='Real results'!D10),2,0),0),0),0) -> 0 | AS11: =IFERROR(IF(AND(ISNUMBER('Real results'!C10),ISNUMBER('Real results'!D10),ISNUMBER('Raw data'!AS10),ISNUMBER('Raw data'!AT10)),IF(SIGN('Raw data'!AS10-'Raw data'!AT10)=SIGN('Real results'!C10-'Real results'!D10),2+IF(AND('Raw data'!AS10='Real results'!C10,'Raw data'!AT10='Real results'!D10),2,0),0),0),0) -> 0 | AU11: =IFERROR(IF(AND(ISNUMBER('Real results'!C10),ISNUMBER('Real results'!D10),ISNUMBER('Raw data'!AU10),ISNUMBER('Raw data'!AV10)),IF(SIGN('Raw data'!AU10-'Raw data'!AV10)=SIGN('Real results'!C10-'Real results'!D10),2+IF(AND('Raw data'!AU10='Real results'!C10,'Raw data'!AV10='Real results'!D10),2,0),0),0),0) -> 0 | AW11: =IFERROR(IF(AND(ISNUMBER('Real results'!C10),ISNUMBER('Real results'!D10),ISNUMBER('Raw data'!AW10),ISNUMBER('Raw data'!AX10)),IF(SIGN('Raw data'!AW10-'Raw data'!AX10)=SIGN('Real results'!C10-'Real results'!D10),2+IF(AND('Raw data'!AW10='Real results'!C10,'Raw data'!AX10='Real results'!D10),2,0),0),0),0) -> 0 | AY11: =IFERROR(IF(AND(ISNUMBER('Real results'!C10),ISNUMBER('Real results'!D10),ISNUMBER('Raw data'!AY10),ISNUMBER('Raw data'!AZ10)),IF(SIGN('Raw data'!AY10-'Raw data'!AZ10)=SIGN('Real results'!C10-'Real results'!D10),2+IF(AND('Raw data'!AY10='Real results'!C10,'Raw data'!AZ10='Real results'!D10),2,0),0),0),0) -> 0 | BA11: =IFERROR(IF(AND(ISNUMBER('Real results'!C10),ISNUMBER('Real results'!D10),ISNUMBER('Raw data'!BA10),ISNUMBER('Raw data'!BB10)),IF(SIGN('Raw data'!BA10-'Raw data'!BB10)=SIGN('Real results'!C10-'Real results'!D10),2+IF(AND('Raw data'!BA10='Real results'!C10,'Raw data'!BB10='Real results'!D10),2,0),0),0),0) -> 0 | BC11: =IFERROR(IF(AND(ISNUMBER('Real results'!C10),ISNUMBER('Real results'!D10),ISNUMBER('Raw data'!BC10),ISNUMBER('Raw data'!BD10)),IF(SIGN('Raw data'!BC10-'Raw data'!BD10)=SIGN('Real results'!C10-'Real results'!D10),2+IF(AND('Raw data'!BC10='Real results'!C10,'Raw data'!BD10='Real results'!D10),2,0),0),0),0) -> 0 | BE11: =IFERROR(IF(AND(ISNUMBER('Real results'!C10),ISNUMBER('Real results'!D10),ISNUMBER('Raw data'!BE10),ISNUMBER('Raw data'!BF10)),IF(SIGN('Raw data'!BE10-'Raw data'!BF10)=SIGN('Real results'!C10-'Real results'!D10),2+IF(AND('Raw data'!BE10='Real results'!C10,'Raw data'!BF10='Real results'!D10),2,0),0),0),0) -> 0 | BG11: =IFERROR(IF(AND(ISNUMBER('Real results'!C10),ISNUMBER('Real results'!D10),ISNUMBER('Raw data'!BG10),ISNUMBER('Raw data'!BH10)),IF(SIGN('Raw data'!BG10-'Raw data'!BH10)=SIGN('Real results'!C10-'Real results'!D10),2+IF(AND('Raw data'!BG10='Real results'!C10,'Raw data'!BH10='Real results'!D10),2,0),0),0),0) -> 0 | BI11: =IFERROR(IF(AND(ISNUMBER('Real results'!C10),ISNUMBER('Real results'!D10),ISNUMBER('Raw data'!BI10),ISNUMBER('Raw data'!BJ10)),IF(SIGN('Raw data'!BI10-'Raw data'!BJ10)=SIGN('Real results'!C10-'Real results'!D10),2+IF(AND('Raw data'!BI10='Real results'!C10,'Raw data'!BJ10='Real results'!D10),2,0),0),0),0) -> 0
B12: GA-M5: Czech Rep. vs Mexico | C12: =IFERROR(IF(AND(ISNUMBER('Real results'!C11),ISNUMBER('Real results'!D11),ISNUMBER('Raw data'!C9),ISNUMBER('Raw data'!D9)),IF(SIGN('Raw data'!C9-'Raw data'!D9)=SIGN('Real results'!C11-'Real results'!D11),2+IF(AND('Raw data'!C9='Real results'!C11,'Raw data'!D9='Real results'!D11),2,0),0),0),0) -> 0 | E12: =IFERROR(IF(AND(ISNUMBER('Real results'!C11),ISNUMBER('Real results'!D11),ISNUMBER('Raw data'!E10),ISNUMBER('Raw data'!F10)),IF(SIGN('Raw data'!E10-'Raw data'!F10)=SIGN('Real results'!C11-'Real results'!D11),2+IF(AND('Raw data'!E10='Real results'!C11,'Raw data'!F10='Real results'!D11),2,0),0),0),0) -> 0 | G12: =IFERROR(IF(AND(ISNUMBER('Real results'!C11),ISNUMBER('Real results'!D11),ISNUMBER('Raw data'!G11),ISNUMBER('Raw data'!H11)),IF(SIGN('Raw data'!G11-'Raw data'!H11)=SIGN('Real results'!C11-'Real results'!D11),2+IF(AND('Raw data'!G11='Real results'!C11,'Raw data'!H11='Real results'!D11),2,0),0),0),0) -> 0 | I12: =IFERROR(IF(AND(ISNUMBER('Real results'!C11),ISNUMBER('Real results'!D11),ISNUMBER('Raw data'!I11),ISNUMBER('Raw data'!J11)),IF(SIGN('Raw data'!I11-'Raw data'!J11)=SIGN('Real results'!C11-'Real results'!D11),2+IF(AND('Raw data'!I11='Real results'!C11,'Raw data'!J11='Real results'!D11),2,0),0),0),0) -> 2 | K12: =IFERROR(IF(AND(ISNUMBER('Real results'!C11),ISNUMBER('Real results'!D11),ISNUMBER('Raw data'!K11),ISNUMBER('Raw data'!L11)),IF(SIGN('Raw data'!K11-'Raw data'!L11)=SIGN('Real results'!C11-'Real results'!D11),2+IF(AND('Raw data'!K11='Real results'!C11,'Raw data'!L11='Real results'!D11),2,0),0),0),0) -> 2 | M12: =IFERROR(IF(AND(ISNUMBER('Real results'!C11),ISNUMBER('Real results'!D11),ISNUMBER('Raw data'!M11),ISNUMBER('Raw data'!N11)),IF(SIGN('Raw data'!M11-'Raw data'!N11)=SIGN('Real results'!C11-'Real results'!D11),2+IF(AND('Raw data'!M11='Real results'!C11,'Raw data'!N11='Real results'!D11),2,0),0),0),0) -> 0 | O12: =IFERROR(IF(AND(ISNUMBER('Real results'!C11),ISNUMBER('Real results'!D11),ISNUMBER('Raw data'!O11),ISNUMBER('Raw data'!P11)),IF(SIGN('Raw data'!O11-'Raw data'!P11)=SIGN('Real results'!C11-'Real results'!D11),2+IF(AND('Raw data'!O11='Real results'!C11,'Raw data'!P11='Real results'!D11),2,0),0),0),0) -> 0 | Q12: =IFERROR(IF(AND(ISNUMBER('Real results'!C11),ISNUMBER('Real results'!D11),ISNUMBER('Raw data'!Q11),ISNUMBER('Raw data'!R11)),IF(SIGN('Raw data'!Q11-'Raw data'!R11)=SIGN('Real results'!C11-'Real results'!D11),2+IF(AND('Raw data'!Q11='Real results'!C11,'Raw data'!R11='Real results'!D11),2,0),0),0),0) -> 0 | S12: =IFERROR(IF(AND(ISNUMBER('Real results'!C11),ISNUMBER('Real results'!D11),ISNUMBER('Raw data'!S11),ISNUMBER('Raw data'!T11)),IF(SIGN('Raw data'!S11-'Raw data'!T11)=SIGN('Real results'!C11-'Real results'!D11),2+IF(AND('Raw data'!S11='Real results'!C11,'Raw data'!T11='Real results'!D11),2,0),0),0),0) -> 0 | U12: =IFERROR(IF(AND(ISNUMBER('Real results'!C11),ISNUMBER('Real results'!D11),ISNUMBER('Raw data'!U11),ISNUMBER('Raw data'!V11)),IF(SIGN('Raw data'!U11-'Raw data'!V11)=SIGN('Real results'!C11-'Real results'!D11),2+IF(AND('Raw data'!U11='Real results'!C11,'Raw data'!V11='Real results'!D11),2,0),0),0),0) -> 0 | W12: =IFERROR(IF(AND(ISNUMBER('Real results'!C11),ISNUMBER('Real results'!D11),ISNUMBER('Raw data'!W11),ISNUMBER('Raw data'!X11)),IF(SIGN('Raw data'!W11-'Raw data'!X11)=SIGN('Real results'!C11-'Real results'!D11),2+IF(AND('Raw data'!W11='Real results'!C11,'Raw data'!X11='Real results'!D11),2,0),0),0),0) -> 0 | Y12: =IFERROR(IF(AND(ISNUMBER('Real results'!C11),ISNUMBER('Real results'!D11),ISNUMBER('Raw data'!Y11),ISNUMBER('Raw data'!Z11)),IF(SIGN('Raw data'!Y11-'Raw data'!Z11)=SIGN('Real results'!C11-'Real results'!D11),2+IF(AND('Raw data'!Y11='Real results'!C11,'Raw data'!Z11='Real results'!D11),2,0),0),0),0) -> 0 | AA12: =IFERROR(IF(AND(ISNUMBER('Real results'!C11),ISNUMBER('Real results'!D11),ISNUMBER('Raw data'!AA11),ISNUMBER('Raw data'!AB11)),IF(SIGN('Raw data'!AA11-'Raw data'!AB11)=SIGN('Real results'!C11-'Real results'!D11),2+IF(AND('Raw data'!AA11='Real results'!C11,'Raw data'!AB11='Real results'!D11),2,0),0),0),0) -> 0 | AC12: =IFERROR(IF(AND(ISNUMBER('Real results'!C11),ISNUMBER('Real results'!D11),ISNUMBER('Raw data'!AC11),ISNUMBER('Raw data'!AD11)),IF(SIGN('Raw data'!AC11-'Raw data'!AD11)=SIGN('Real results'!C11-'Real results'!D11),2+IF(AND('Raw data'!AC11='Real results'!C11,'Raw data'!AD11='Real results'!D11),2,0),0),0),0) -> 0 | AE12: =IFERROR(IF(AND(ISNUMBER('Real results'!C11),ISNUMBER('Real results'!D11),ISNUMBER('Raw data'!AE11),ISNUMBER('Raw data'!AF11)),IF(SIGN('Raw data'!AE11-'Raw data'!AF11)=SIGN('Real results'!C11-'Real results'!D11),2+IF(AND('Raw data'!AE11='Real results'!C11,'Raw data'!AF11='Real results'!D11),2,0),0),0),0) -> 0 | AG12: =IFERROR(IF(AND(ISNUMBER('Real results'!C11),ISNUMBER('Real results'!D11),ISNUMBER('Raw data'!AG11),ISNUMBER('Raw data'!AH11)),IF(SIGN('Raw data'!AG11-'Raw data'!AH11)=SIGN('Real results'!C11-'Real results'!D11),2+IF(AND('Raw data'!AG11='Real results'!C11,'Raw data'!AH11='Real results'!D11),2,0),0),0),0) -> 0 | AI12: =IFERROR(IF(AND(ISNUMBER('Real results'!C11),ISNUMBER('Real results'!D11),ISNUMBER('Raw data'!AI11),ISNUMBER('Raw data'!AJ11)),IF(SIGN('Raw data'!AI11-'Raw data'!AJ11)=SIGN('Real results'!C11-'Real results'!D11),2+IF(AND('Raw data'!AI11='Real results'!C11,'Raw data'!AJ11='Real results'!D11),2,0),0),0),0) -> 0 | AK12: =IFERROR(IF(AND(ISNUMBER('Real results'!C11),ISNUMBER('Real results'!D11),ISNUMBER('Raw data'!AK11),ISNUMBER('Raw data'!AL11)),IF(SIGN('Raw data'!AK11-'Raw data'!AL11)=SIGN('Real results'!C11-'Real results'!D11),2+IF(AND('Raw data'!AK11='Real results'!C11,'Raw data'!AL11='Real results'!D11),2,0),0),0),0) -> 0 | AM12: =IFERROR(IF(AND(ISNUMBER('Real results'!C11),ISNUMBER('Real results'!D11),ISNUMBER('Raw data'!AM11),ISNUMBER('Raw data'!AN11)),IF(SIGN('Raw data'!AM11-'Raw data'!AN11)=SIGN('Real results'!C11-'Real results'!D11),2+IF(AND('Raw data'!AM11='Real results'!C11,'Raw data'!AN11='Real results'!D11),2,0),0),0),0) -> 0 | AO12: =IFERROR(IF(AND(ISNUMBER('Real results'!C11),ISNUMBER('Real results'!D11),ISNUMBER('Raw data'!AO11),ISNUMBER('Raw data'!AP11)),IF(SIGN('Raw data'!AO11-'Raw data'!AP11)=SIGN('Real results'!C11-'Real results'!D11),2+IF(AND('Raw data'!AO11='Real results'!C11,'Raw data'!AP11='Real results'!D11),2,0),0),0),0) -> 0 | AQ12: =IFERROR(IF(AND(ISNUMBER('Real results'!C11),ISNUMBER('Real results'!D11),ISNUMBER('Raw data'!AQ11),ISNUMBER('Raw data'!AR11)),IF(SIGN('Raw data'!AQ11-'Raw data'!AR11)=SIGN('Real results'!C11-'Real results'!D11),2+IF(AND('Raw data'!AQ11='Real results'!C11,'Raw data'!AR11='Real results'!D11),2,0),0),0),0) -> 0 | AS12: =IFERROR(IF(AND(ISNUMBER('Real results'!C11),ISNUMBER('Real results'!D11),ISNUMBER('Raw data'!AS11),ISNUMBER('Raw data'!AT11)),IF(SIGN('Raw data'!AS11-'Raw data'!AT11)=SIGN('Real results'!C11-'Real results'!D11),2+IF(AND('Raw data'!AS11='Real results'!C11,'Raw data'!AT11='Real results'!D11),2,0),0),0),0) -> 0 | AU12: =IFERROR(IF(AND(ISNUMBER('Real results'!C11),ISNUMBER('Real results'!D11),ISNUMBER('Raw data'!AU11),ISNUMBER('Raw data'!AV11)),IF(SIGN('Raw data'!AU11-'Raw data'!AV11)=SIGN('Real results'!C11-'Real results'!D11),2+IF(AND('Raw data'!AU11='Real results'!C11,'Raw data'!AV11='Real results'!D11),2,0),0),0),0) -> 0 | AW12: =IFERROR(IF(AND(ISNUMBER('Real results'!C11),ISNUMBER('Real results'!D11),ISNUMBER('Raw data'!AW11),ISNUMBER('Raw data'!AX11)),IF(SIGN('Raw data'!AW11-'Raw data'!AX11)=SIGN('Real results'!C11-'Real results'!D11),2+IF(AND('Raw data'!AW11='Real results'!C11,'Raw data'!AX11='Real results'!D11),2,0),0),0),0) -> 0 | AY12: =IFERROR(IF(AND(ISNUMBER('Real results'!C11),ISNUMBER('Real results'!D11),ISNUMBER('Raw data'!AY11),ISNUMBER('Raw data'!AZ11)),IF(SIGN('Raw data'!AY11-'Raw data'!AZ11)=SIGN('Real results'!C11-'Real results'!D11),2+IF(AND('Raw data'!AY11='Real results'!C11,'Raw data'!AZ11='Real results'!D11),2,0),0),0),0) -> 0 | BA12: =IFERROR(IF(AND(ISNUMBER('Real results'!C11),ISNUMBER('Real results'!D11),ISNUMBER('Raw data'!BA11),ISNUMBER('Raw data'!BB11)),IF(SIGN('Raw data'!BA11-'Raw data'!BB11)=SIGN('Real results'!C11-'Real results'!D11),2+IF(AND('Raw data'!BA11='Real results'!C11,'Raw data'!BB11='Real results'!D11),2,0),0),0),0) -> 0 | BC12: =IFERROR(IF(AND(ISNUMBER('Real results'!C11),ISNUMBER('Real results'!D11),ISNUMBER('Raw data'!BC11),ISNUMBER('Raw data'!BD11)),IF(SIGN('Raw data'!BC11-'Raw data'!BD11)=SIGN('Real results'!C11-'Real results'!D11),2+IF(AND('Raw data'!BC11='Real results'!C11,'Raw data'!BD11='Real results'!D11),2,0),0),0),0) -> 0 | BE12: =IFERROR(IF(AND(ISNUMBER('Real results'!C11),ISNUMBER('Real results'!D11),ISNUMBER('Raw data'!BE11),ISNUMBER('Raw data'!BF11)),IF(SIGN('Raw data'!BE11-'Raw data'!BF11)=SIGN('Real results'!C11-'Real results'!D11),2+IF(AND('Raw data'!BE11='Real results'!C11,'Raw data'!BF11='Real results'!D11),2,0),0),0),0) -> 0 | BG12: =IFERROR(IF(AND(ISNUMBER('Real results'!C11),ISNUMBER('Real results'!D11),ISNUMBER('Raw data'!BG11),ISNUMBER('Raw data'!BH11)),IF(SIGN('Raw data'!BG11-'Raw data'!BH11)=SIGN('Real results'!C11-'Real results'!D11),2+IF(AND('Raw data'!BG11='Real results'!C11,'Raw data'!BH11='Real results'!D11),2,0),0),0),0) -> 0 | BI12: =IFERROR(IF(AND(ISNUMBER('Real results'!C11),ISNUMBER('Real results'!D11),ISNUMBER('Raw data'!BI11),ISNUMBER('Raw data'!BJ11)),IF(SIGN('Raw data'!BI11-'Raw data'!BJ11)=SIGN('Real results'!C11-'Real results'!D11),2+IF(AND('Raw data'!BI11='Real results'!C11,'Raw data'!BJ11='Real results'!D11),2,0),0),0),0) -> 0
